91951477042977	{"id":"md","event":"subscribe","arg":{"channel":"books","instId":"BTC-USDT-SWAP"},"connId":"73220c7f"}
91951477042977	{"id":"md","event":"subscribe","arg":{"channel":"bbo-tbt","instId":"BTC-USDT-SWAP"},"connId":"73220c7f"}
91951477042977	{"id":"md","event":"subscribe","arg":{"channel":"trades","instId":"BTC-USDT-SWAP"},"connId":"73220c7f"}
91951541787274	{"arg":{"channel":"trades","instId":"BTC-USDT-SWAP"},"data":[{"instId":"BTC-USDT-SWAP","tradeId":"2953620209","px":"84093.4","sz":"0.01","side":"sell","ts":"1790439594782","count":"1","source":"0","seqId":342177336862}]}
91951720048981	{"arg":{"channel":"bbo-tbt","instId":"BTC-USDT-SWAP"},"data":[{"asks":[["84093.5","667.19","0","70"]],"bids":[["84093.4","570.27","0","83"]],"ts":"1790439594900","seqId":342177336945}]}
91951720090117	{"arg":{"channel":"books","instId":"BTC-USDT-SWAP"},"action":"snapshot","data":[{"asks":[["84093.5","667.19","0","70"],["84093.6","0.51","0","1"],["84094","0.01","0","1"],["84094.1","0.02","0","2"],["84094.4","0.02","0","2"],["84095.1","0.01","0","1"],["84095.2","0.05","0","1"],["84095.5","0.03","0","3"],["84095.6","61","0","1"],["84095.8","0.1","0","1"],["84095.9","0.01","0","1"],["84096","0.01","0","1"],["84096.3","0.01","0","1"],["84096.6","0.02","0","2"],["84096.8","0.01","0","1"],["84097","0.01","0","1"],["84097.1","0.01","0","1"],["84097.7","0.03","0","3"],["84097.8","8.53","0","4"],["84097.9","0.02","0","2"],["84098.1","0.13","0","4"],["84098.2","0.6","0","1"],["84098.7","0.01","0","1"],["84099","0.01","0","1"],["84099.2","0.02","0","2"],["84099.5","0.12","0","1"],["84099.6","2.39","0","3"],["84099.7","28.58","0","7"],["84099.8","0.02","0","2"],["84099.9","373.12","0","6"],["84100","1249.65","0","11"],["84100.1","0.02","0","2"],["84100.3","0.01","0","1"],["84100.4","0.11","0","2"],["84100.5","2.37","0","1"],["84100.7","0.01","0","1"],["84100.8","0.02","0","2"],["84100.9","0.05","0","4"],["84101","23.79","0","2"],["84101.1","0.11","0","4"],["84101.2","13.02","0","2"],["84101.6","0.71","0","2"],["84101.8","0.12","0","3"],["84101.9","108.95","0","4"],["84102","228.81","0","10"],["84102.2","0.01","0","1"],["84102.4","0.02","0","2"],["84102.5","0.02","0","2"],["84102.6","44.68","0","2"],["84102.7","0.11","0","2"],["84102.8","44.67","0","1"],["84103","0.01","0","1"],["84103.3","0.6","0","1"],["84103.4","0.02","0","2"],["84103.6","0.14","0","3"],["84103.8","0.01","0","1"],["84103.9","22.68","0","3"],["84104","0.02","0","2"],["84104.2","0.01","0","1"],["84104.3","8.4","0","1"],["84104.4","0.02","0","2"],["84104.5","0.03","0","3"],["84104.6","0.01","0","1"],["84104.7","44.67","0","1"],["84104.8","0.01","0","1"],["84104.9","0.01","0","1"],["84105","0.13","0","4"],["84105.2","0.01","0","1"],["84105.5","12.6","0","1"],["84105.6","0.02","0","2"],["84105.7","0.01","0","1"],["84105.9","0.5","0","1"],["84106","0.03","0","3"],["84106.1","0.01","0","1"],["84106.2","0.01","0","1"],["84106.4","0.01","0","1"],["84106.5","0.01","0","1"],["84106.7","0.19","0","2"],["84106.8","0.02","0","2"],["84106.9","32.37","0","1"],["84107","0.01","0","1"],["84107.1","0.01","0","1"],["84107.3","0.1","0","1"],["84107.4","0.17","0","4"],["84107.5","21.4","0","1"],["84107.8","0.02","0","2"],["84107.9","0.01","0","1"],["84108","92.36","0","5"],["84108.2","0.01","0","1"],["84108.3","0.02","0","2"],["84108.4","0.02","0","2"],["84108.5","5.66","0","5"],["84108.7","3.01","0","1"],["84108.8","0.01","0","1"],["84109","0.75","0","1"],["84109.1","0.27","0","2"],["84109.2","0.18","0","6"],["84109.3","2.61","0","4"],["84109.5","0.01","0","1"],["84109.6","1.29","0","2"],["84109.7","459.25","0","5"],["84109.8","904.57","0","3"],["84109.9","11.94","0","6"],["84110","2535.29","0","125"],["84110.1","0.13","0","3"],["84110.2","1.01","0","2"],["84110.3","0.01","0","1"],["84110.4","1.04","0","2"],["84110.5","4.7","0","1"],["84110.8","0.11","0","2"],["84110.9","0.02","0","2"],["84111","21.73","0","4"],["84111.1","0.03","0","1"],["84111.2","0.03","0","3"],["84111.3","75.63","0","2"],["84111.5","0.01","0","1"],["84111.7","1.73","0","11"],["84111.9","0.1","0","1"],["84112","0.12","0","3"],["84112.1","4.47","0","3"],["84112.2","0.24","0","1"],["84112.3","0.01","0","1"],["84112.4","50.66","0","2"],["84112.5","70.26","0","6"],["84112.6","312.83","0","2"],["84112.8","11.91","0","1"],["84112.9","3","0","1"],["84113","237.82","0","2"],["84113.1","1.64","0","1"],["84113.3","0.04","0","4"],["84113.4","319.06","0","5"],["84113.5","167.81","0","2"],["84113.6","0.6","0","1"],["84113.7","0.02","0","2"],["84113.8","226.29","0","4"],["84114","47.67","0","2"],["84114.1","0.01","0","1"],["84114.2","0.85","0","2"],["84114.3","0.17","0","3"],["84114.4","0.01","0","1"],["84114.5","67.01","0","1"],["84114.6","59.61","0","4"],["84114.9","0.02","0","2"],["84115","47.66","0","1"],["84115.1","0.2","0","3"],["84115.2","0.03","0","3"],["84115.4","0.13","0","3"],["84115.5","0.1","0","3"],["84115.6","8.98","0","2"],["84115.7","3.64","0","2"],["84116","0.01","0","1"],["84116.1","29.79","0","1"],["84116.2","0.01","0","1"],["84116.3","91.27","0","3"],["84116.5","9.66","0","2"],["84116.6","0.02","0","2"],["84116.7","59.58","0","1"],["84116.8","0.02","0","2"],["84116.9","0.01","0","1"],["84117","0.61","0","3"],["84117.1","69.97","0","1"],["84117.3","0.01","0","1"],["84117.4","0.01","0","1"],["84117.5","35.77","0","1"],["84117.6","0.03","0","3"],["84117.7","0.04","0","2"],["84117.8","0.01","0","1"],["84117.9","0.03","0","3"],["84118","310.95","0","2"],["84118.1","20.51","0","2"],["84118.4","0.02","0","2"],["84118.5","421.21","0","6"],["84118.6","5.74","0","2"],["84118.7","14.54","0","4"],["84118.8","47.07","0","2"],["84118.9","11.93","0","2"],["84119","0.01","0","1"],["84119.1","0.06","0","1"],["84119.2","11.94","0","3"],["84119.3","44.7","0","3"],["84119.4","0.04","0","2"],["84119.5","12.08","0","3"],["84119.6","11.93","0","2"],["84119.7","0.02","0","2"],["84119.8","141.75","0","5"],["84119.9","63.6","0","2"],["84120","0.82","0","13"],["84120.1","14.49","0","3"],["84120.4","0.01","0","1"],["84120.5","0.01","0","1"],["84120.6","0.01","0","1"],["84120.7","0.01","0","1"],["84120.9","0.04","0","2"],["84121.1","2.37","0","1"],["84121.2","12.5","0","2"],["84121.3","0.03","0","3"],["84121.4","69.97","0","1"],["84121.6","0.03","0","3"],["84121.7","0.02","0","2"],["84121.8","0.03","0","3"],["84121.9","14.1","0","1"],["84122.2","0.96","0","2"],["84122.3","11.92","0","1"],["84122.4","0.01","0","1"],["84122.5","0.01","0","1"],["84122.7","9.18","0","2"],["84123","1.32","0","5"],["84123.1","3.48","0","2"],["84123.2","0.01","0","1"],["84123.3","1.16","0","2"],["84123.4","12.42","0","2"],["84123.6","0.01","0","1"],["84123.9","11.92","0","1"],["84124","0.11","0","4"],["84124.2","8.47","0","1"],["84124.3","0.01","0","1"],["84124.4","0.13","0","2"],["84124.5","79.89","0","3"],["84124.6","132.1","0","5"],["84124.7","0.41","0","7"],["84124.8","0.04","0","4"],["84125","0.14","0","6"],["84125.2","0.01","0","1"],["84125.4","0.01","0","1"],["84125.6","14.03","0","4"],["84125.7","0.11","0","4"],["84125.8","0.92","0","3"],["84125.9","70.04","0","1"],["84126","35.89","0","6"],["84126.1","1.76","0","4"],["84126.2","0.01","0","1"],["84126.3","0.57","0","17"],["84126.4","29.71","0","1"],["84126.5","0.03","0","3"],["84126.6","284.05","0","1"],["84126.7","12.08","0","2"],["84126.9","0.02","0","2"],["84127","17.25","0","2"],["84127.1","2.86","0","2"],["84127.2","185.44","0","4"],["84127.4","0.02","0","1"],["84127.5","0.01","0","1"],["84127.7","3.17","0","1"],["84127.8","11.93","0","2"],["84127.9","0.11","0","2"],["84128","0.17","0","6"],["84128.1","0.27","0","1"],["84128.2","2.87","0","3"],["84128.3","0.25","0","3"],["84128.4","260.14","0","1"],["84128.5","8.32","0","1"],["84128.6","11.92","0","1"],["84128.7","0.02","0","2"],["84128.8","48.35","0","2"],["84128.9","12.16","0","4"],["84129","0.01","0","1"],["84129.1","0.05","0","2"],["84129.4","0.1","0","1"],["84129.5","14.13","0","10"],["84129.7","0.59","0","1"],["84129.8","0.01","0","1"],["84129.9","0.33","0","4"],["84130","53.46","0","10"],["84130.1","0.01","0","1"],["84130.2","70.07","0","4"],["84130.3","3","0","1"],["84130.7","0.01","0","1"],["84130.8","0.01","0","1"],["84130.9","2.85","0","1"],["84131.1","12.38","0","3"],["84131.2","11.93","0","2"],["84131.4","0.04","0","4"],["84131.5","0.02","0","2"],["84131.6","0.02","0","2"],["84131.7","0.04","0","2"],["84131.8","353","0","1"],["84131.9","0.02","0","2"],["84132","0.35","0","3"],["84132.1","0.01","0","1"],["84132.2","11.92","0","1"],["84132.3","0.01","0","1"],["84132.5","1.2","0","1"],["84132.7","0.3","0","1"],["84132.8","8.44","0","3"],["84132.9","89.6","0","4"],["84133","85.13","0","6"],["84133.1","0.12","0","1"],["84133.2","0.11","0","2"],["84133.3","17.11","0","16"],["84133.4","0.01","0","1"],["84133.6","0.72","0","2"],["84133.7","0.02","0","2"],["84133.8","0.01","0","1"],["84133.9","1.01","0","2"],["84134","0.01","0","1"],["84134.1","0.83","0","1"],["84134.4","11.97","0","6"],["84134.5","70.07","0","3"],["84134.6","0.02","0","1"],["84134.7","0.06","0","4"],["84134.8","1.54","0","12"],["84135","0.46","0","3"],["84135.1","35.79","0","3"],["84135.3","2.56","0","1"],["84135.5","24.57","0","4"],["84135.7","0.6","0","1"],["84135.9","0.76","0","2"],["84136","26.68","0","5"],["84136.1","366.97","0","4"],["84136.2","57.67","0","2"],["84136.3","0.09","0","2"],["84136.4","11.98","0","2"],["84136.8","2.93","0","4"],["84136.9","0.8","0","26"],["84137","0.05","0","5"],["84137.1","8.56","0","3"],["84137.3","0.08","0","2"],["84137.5","2.88","0","2"],["84137.6","0.01","0","1"],["84137.7","0.01","0","1"],["84137.8","0.2","0","2"],["84137.9","0.02","0","2"],["84138","6.09","0","3"],["84138.1","0.03","0","3"],["84138.3","48.3","0","3"],["84138.4","0.01","0","1"],["84138.6","0.83","0","13"],["84138.7","0.02","0","2"],["84138.9","2.77","0","1"],["84139","0.01","0","1"],["84139.1","88.69","0","1"],["84139.2","0.92","0","1"],["84139.4","13.44","0","2"],["84139.5","5.76","0","3"],["84139.6","0.02","0","2"],["84139.8","11.92","0","1"],["84139.9","2.11","0","25"],["84140","9.43","0","15"],["84140.1","0.61","0","2"],["84140.2","138.05","0","4"],["84140.3","0.03","0","2"],["84140.4","0.01","0","1"],["84140.5","0.01","0","1"],["84140.8","0.01","0","1"],["84140.9","2.85","0","1"],["84141","0.01","0","1"],["84141.1","47.54","0","4"],["84141.2","89.29","0","3"],["84141.3","19.3","0","1"],["84141.4","8.31","0","1"],["84141.9","58.89","0","10"],["84142","1.11","0","3"],["84142.1","0.01","0","1"],["84142.2","11.89","0","1"],["84142.4","2.85","0","1"],["84142.6","23.36","0","1"],["84142.7","0.09","0","2"],["84142.8","0.9","0","7"],["84142.9","0.25","0","7"],["84143.2","0.9","0","1"],["84143.4","0.25","0","2"],["84143.5","10.07","0","4"],["84143.6","135.95","0","3"],["84143.8","0.02","0","2"],["84143.9","297.22","0","1"],["84144","8.89","0","7"],["84144.1","0.49","0","2"],["84144.3","0.05","0","3"],["84144.4","150","0","1"],["84144.5","0.01","0","1"],["84144.6","0.04","0","1"],["84144.7","4.99","0","3"],["84144.9","0.08","0","6"],["84145","5","0","1"],["84145.1","0.62","0","3"],["84145.2","11.92","0","1"],["84145.3","2.38","0","1"],["84145.5","2.56","0","1"],["84145.6","0.01","0","1"],["84145.7","11.44","0","2"],["84145.9","0.01","0","1"],["84146","7.12","0","1"],["84146.2","1.85","0","5"],["84146.4","0.03","0","3"],["84146.5","0.01","0","1"],["84146.6","0.01","0","1"],["84146.7","2.71","0","2"],["84147","21.58","0","4"],["84147.2","0.02","0","2"],["84147.4","0.95","0","1"],["84147.5","0.03","0","2"],["84147.6","26.79","0","2"],["84147.8","40.74","0","2"],["84147.9","0.01","0","1"],["84148.1","0.01","0","1"],["84148.2","2.96","0","4"],["84148.3","1.17","0","3"],["84148.4","0.23","0","2"],["84148.5","0.03","0","2"],["84148.6","0.02","0","1"]],"bids":[["84093.4","570.27","0","83"],["84093.3","0.12","0","3"],["84093.2","0.07","0","2"],["84093.1","0.06","0","1"],["84093","0.06","0","1"],["84092.9","23.88","0","2"],["84092.7","0.03","0","3"],["84092.6","50.62","0","3"],["84092.5","5.03","0","1"],["84092.4","0.01","0","1"],["84092.3","0.02","0","2"],["84092.2","120.06","0","4"],["84092.1","35.81","0","2"],["84091.8","0.01","0","1"],["84091.4","0.09","0","2"],["84091.2","0.01","0","1"],["84090.9","5.94","0","2"],["84090.8","0.1","0","1"],["84090.6","0.01","0","1"],["84090.5","0.01","0","1"],["84090.4","16.17","0","2"],["84090.3","0.6","0","1"],["84090.2","0.03","0","3"],["84090.1","17.11","0","1"],["84090","0.47","0","3"],["84089.9","0.02","0","2"],["84089.8","0.72","0","3"],["84089.7","1.19","0","1"],["84089.5","0.01","0","1"],["84089.2","2.39","0","3"],["84089.1","70.86","0","2"],["84089","0.12","0","3"],["84088.9","18.27","0","2"],["84088.8","0.01","0","1"],["84088.7","12.06","0","3"],["84088.6","237.95","0","4"],["84088.5","12.84","0","1"],["84088.3","0.02","0","2"],["84088.2","219.23","0","5"],["84088.1","0.02","0","1"],["84088","0.02","0","2"],["84087.9","23.67","0","5"],["84087.8","11.96","0","3"],["84087.4","0.01","0","1"],["84087","0.01","0","1"],["84086.8","0.27","0","3"],["84086.7","59.58","0","1"],["84086.6","0.03","0","3"],["84086.5","29.71","0","2"],["84086.4","0.01","0","1"],["84086.2","10.06","0","3"],["84085.9","0.01","0","1"],["84085.8","42.85","0","6"],["84085.6","0.1","0","1"],["84085.3","0.91","0","2"],["84085.2","249.01","0","4"],["84085","0.01","0","1"],["84084.9","259.21","0","5"],["84084.8","86.05","0","2"],["84084.4","0.02","0","2"],["84084.3","0.01","0","1"],["84084.2","0.01","0","1"],["84084.1","220.6","0","2"],["84084","244.68","0","6"],["84083.8","76.89","0","3"],["84083.5","0.01","0","1"],["84083.4","92.48","0","1"],["84083.2","0.02","0","2"],["84083.1","91.16","0","2"],["84083","0.1","0","1"],["84082.9","0.01","0","1"],["84082.4","0.02","0","2"],["84082","0.01","0","1"],["84081.9","0.01","0","1"],["84081.8","70.41","0","2"],["84081.7","0.01","0","1"],["84081.5","0.01","0","1"],["84081.4","0.2","0","3"],["84081.3","0.01","0","1"],["84081.1","0.74","0","2"],["84081","0.05","0","5"],["84080.9","8.41","0","2"],["84080.8","1.22","0","2"],["84080.7","0.01","0","1"],["84080.6","0.01","0","1"],["84080.5","86.04","0","1"],["84080.4","0.1","0","1"],["84080.2","0.01","0","1"],["84080.1","0.01","0","1"],["84080","238.89","0","5"],["84079.9","61.28","0","4"],["84079.8","0.74","0","3"],["84079.7","238.4","0","2"],["84079.6","264.76","0","3"],["84079.5","11.91","0","2"],["84079.4","75.02","0","4"],["84078.9","0.01","0","1"],["84078.8","0.01","0","1"],["84078.6","0.01","0","1"],["84078.4","2.37","0","1"],["84078.2","0.01","0","1"],["84078","0.01","0","1"],["84077.8","0.1","0","1"],["84077.7","0.02","0","2"],["84077.6","0.6","0","1"],["84077.4","0.01","0","1"],["84077.2","0.05","0","2"],["84077.1","122.89","0","1"],["84076.8","0.01","0","1"],["84076.7","0.01","0","1"],["84076.6","2.38","0","2"],["84076.5","1","0","1"],["84076.4","0.01","0","1"],["84076.3","108.74","0","3"],["84076.2","1.05","0","5"],["84076.1","270.36","0","1"],["84075.8","86.54","0","2"],["84075.7","0.51","0","2"],["84075.6","146.95","0","4"],["84075.5","50.13","0","2"],["84075.4","0.03","0","2"],["84075.1","59.53","0","2"],["84075","2.57","0","2"],["84074.9","0.01","0","1"],["84074.8","91.16","0","2"],["84074.6","0.02","0","2"],["84074.5","14.01","0","2"],["84074.3","0.02","0","2"],["84073.8","0.01","0","1"],["84073.7","0.01","0","1"],["84073.6","0.02","0","2"],["84073.5","3.68","0","2"],["84073.4","167.58","0","1"],["84073.1","0.59","0","1"],["84073","0.01","0","1"],["84072.9","0.05","0","2"],["84072.8","44.69","0","2"],["84072.7","0.02","0","1"],["84072.6","0.6","0","1"],["84072.2","0.01","0","1"],["84072.1","0.02","0","2"],["84072","0.15","0","4"],["84071.8","0.11","0","1"],["84071.6","0.01","0","1"],["84071.5","0.02","0","2"],["84071.4","34.55","0","6"],["84071.3","288.69","0","3"],["84071.2","0.86","0","2"],["84071.1","0.01","0","1"],["84071","210","0","3"],["84070.9","59.6","0","3"],["84070.8","8.93","0","2"],["84070.7","0.51","0","2"],["84070.4","0.01","0","1"],["84070.3","0.02","0","2"],["84070","0.1","0","1"],["84069.8","0.02","0","1"],["84069.5","2.38","0","2"],["84069.4","35.78","0","2"],["84069.2","1.29","0","2"],["84069.1","44.68","0","1"],["84069","0.02","0","2"],["84068.9","0.1","0","1"],["84068.8","77.33","0","3"],["84068.7","323.99","0","2"],["84068.6","0.01","0","1"],["84068.5","220.58","0","1"],["84068.4","44.71","0","4"],["84068.2","29.03","0","5"],["84068","0.01","0","1"],["84067.9","0.01","0","1"],["84067.6","0.02","0","2"],["84067.5","0.02","0","2"],["84067.3","6","0","2"],["84067.2","377.52","0","6"],["84067.1","0.6","0","1"],["84067","11.91","0","1"],["84066.8","0.67","0","2"],["84066.7","0.11","0","1"],["84066.6","0.01","0","1"],["84066.5","99.57","0","2"],["84066.3","0.1","0","1"],["84066.1","0.01","0","1"],["84066","0.01","0","1"],["84065.8","0.53","0","4"],["84065.7","220.52","0","3"],["84065.6","0.02","0","1"],["84065.5","3.08","0","2"],["84065.4","11.93","0","2"],["84065.1","0.01","0","1"],["84065","0.01","0","1"],["84064.9","0.02","0","2"],["84064.8","67.24","0","3"],["84064.7","0.01","0","1"],["84064.6","342.62","0","3"],["84064.5","0.14","0","1"],["84064.3","0.01","0","1"],["84064.2","0.02","0","2"],["84064.1","0.02","0","2"],["84064","427.96","0","3"],["84063.9","0.01","0","1"],["84063.7","0.9","0","1"],["84063.6","0.01","0","1"],["84063.3","0.01","0","1"],["84063.2","0.01","0","1"],["84063.1","0.01","0","1"],["84063","372","0","6"],["84062.9","0.33","0","1"],["84062.6","0.01","0","1"],["84062.5","0.01","0","1"],["84062.3","3","0","1"],["84062.2","0.5","0","1"],["84062","0.01","0","1"],["84061.9","58.32","0","2"],["84061.8","0.76","0","2"],["84061.7","0.99","0","2"],["84061.3","2.86","0","2"],["84061.2","209.98","0","1"],["84061.1","11.92","0","1"],["84060.9","44.4","0","9"],["84060.8","663.49","0","5"],["84060.7","0.51","0","2"],["84060.6","0.01","0","1"],["84060.1","0.07","0","3"],["84060","2.87","0","3"],["84059.9","0.01","0","1"],["84059.8","0.01","0","1"],["84059.7","135.05","0","3"],["84059.6","11.93","0","2"],["84059.3","11.93","0","2"],["84059","11.92","0","1"],["84058.8","0.07","0","5"],["84058.7","11.94","0","3"],["84058.5","4.96","0","3"],["84058.4","11.94","0","3"],["84058.3","273.19","0","2"],["84058.2","91.11","0","1"],["84058.1","11.92","0","1"],["84058","0.01","0","1"],["84057.9","0.01","0","1"],["84057.8","14.49","0","3"],["84057.6","8.48","0","2"],["84057.5","11.94","0","3"],["84057.4","0.01","0","1"],["84057.2","11.92","0","1"],["84057.1","0.17","0","3"],["84057","0.01","0","1"],["84056.9","14.82","0","4"],["84056.8","524.92","0","3"],["84056.7","0.61","0","2"],["84056.6","11.92","0","1"],["84056.4","11.93","0","2"],["84056.3","13.11","0","2"],["84056","150.63","0","2"],["84055.9","0.02","0","1"],["84055.8","0.51","0","2"],["84055.7","12.42","0","2"],["84055.6","43.79","0","2"],["84055.4","11.93","0","2"],["84055.3","0.01","0","1"],["84055.1","11.92","0","1"],["84055","0.15","0","4"],["84054.8","11.93","0","2"],["84054.7","0.01","0","1"],["84054.6","224.84","0","4"],["84054.5","11.92","0","1"],["84054.4","0.01","0","1"],["84054.2","11.93","0","2"],["84054.1","0.02","0","2"],["84054","0.02","0","2"],["84053.9","11.92","0","1"],["84053.6","0.03","0","3"],["84053.4","50.88","0","3"],["84053.2","8.63","0","2"],["84053","2.85","0","1"],["84052.9","47.67","0","2"],["84052.8","0.02","0","2"],["84052.7","219.97","0","1"],["84052.6","17.57","0","1"],["84052.5","11.94","0","2"],["84052.4","47.52","0","2"],["84052.3","0.02","0","2"],["84052.1","11.93","0","2"],["84052","56.37","0","1"],["84051.8","0.29","0","1"],["84051.7","11.62","0","2"],["84051.6","0.01","0","1"],["84051.3","1.22","0","4"],["84051.2","0.01","0","1"],["84051","10.01","0","2"],["84050.9","0.24","0","2"],["84050.8","111.86","0","5"],["84050.7","0.33","0","1"],["84050.5","0.02","0","2"],["84050.4","0.02","0","2"],["84050.2","0.01","0","1"],["84050.1","2.71","0","1"],["84050","7.58","0","23"],["84049.9","91.3","0","1"],["84049.7","0.01","0","1"],["84049.6","1.18","0","1"],["84049.3","2.56","0","1"],["84049","0.91","0","2"],["84048.5","0.01","0","1"],["84048.3","0.02","0","2"],["84048.2","11.93","0","2"],["84048","2.98","0","5"],["84047.8","11.92","0","1"],["84047.7","0.33","0","1"],["84047.6","0.01","0","1"],["84047.5","0.02","0","1"],["84047.4","0.04","0","4"],["84047.3","104.72","0","2"],["84047.2","1.32","0","2"],["84047.1","0.01","0","1"],["84046.6","46.51","0","2"],["84046.5","5.74","0","3"],["84046.4","0.01","0","1"],["84046.2","0.02","0","2"],["84045.7","0.01","0","1"],["84045.5","3.01","0","2"],["84045.4","8.45","0","2"],["84045.2","0.01","0","1"],["84045","0.06","0","5"],["84044.9","300.15","0","6"],["84044.8","94.59","0","4"],["84044.7","51.64","0","2"],["84044.4","0.17","0","1"],["84044.3","0.01","0","1"],["84044","0.18","0","6"],["84043.9","11.92","0","1"],["84043.7","0.01","0","1"],["84043.5","14.77","0","3"],["84043.3","0.03","0","3"],["84042.9","225.6","0","5"],["84042.8","0.67","0","1"],["84042.7","0.01","0","1"],["84042.4","0.01","0","1"],["84042.2","0.01","0","1"],["84042.1","0.01","0","1"],["84042","0.02","0","2"],["84041.9","0.02","0","1"],["84041.7","38.95","0","3"],["84041.6","90.78","0","3"],["84041.4","0.02","0","2"],["84041.3","0.01","0","1"],["84041.1","8.5","0","3"],["84041","0.02","0","2"],["84040.8","0.01","0","1"],["84040.7","0.02","0","2"],["84040.6","43.53","0","2"],["84040.5","0.01","0","1"],["84040.4","9.69","0","1"],["84040.3","0.75","0","2"],["84040.2","0.01","0","1"],["84040","0.36","0","7"],["84039.8","0.01","0","1"],["84039.7","71.21","0","1"],["84039.6","11.93","0","2"],["84039.5","0.66","0","2"],["84039.3","0.01","0","1"],["84039.2","11.92","0","1"],["84039.1","0.31","0","3"],["84039","0.01","0","1"],["84038.7","0.33","0","1"],["84038.5","0.11","0","1"],["84038.4","0.01","0","1"],["84038.3","19.31","0","3"],["84037.9","48.58","0","2"],["84037.8","0.01","0","1"],["84037.7","2.77","0","1"],["84037.6","0.01","0","1"],["84037.5","51.34","0","4"],["84037.4","0.33","0","1"],["84037.3","0.02","0","2"],["84037.1","0.01","0","1"],["84036.8","8.4","0","1"],["84036.7","18.29","0","2"],["84036.6","0.59","0","1"],["84036.2","0.95","0","1"],["84036","8.46","0","2"],["84035.9","0.03","0","2"],["84035.6","32.68","0","3"],["84035.5","0.6","0","1"],["84035.4","3.45","0","2"],["84035.3","11.96","0","2"],["84035.2","0.01","0","1"],["84034.9","11.94","0","3"],["84034.8","0.02","0","2"],["84034.5","0.02","0","2"],["84034.2","0.01","0","1"],["84034","0.02","0","2"],["84033.8","0.02","0","2"],["84033.7","338.6","0","2"],["84033.6","0.01","0","1"],["84033.3","90.91","0","2"],["84033","0.02","0","2"],["84032.8","0.47","0","1"],["84032.5","8.5","0","1"],["84032","0.04","0","4"]],"ts":"1790439594900","checksum":0,"seqId":342177336945,"prevSeqId":-1}]}
91951720090117	{"arg":{"channel":"bbo-tbt","instId":"BTC-USDT-SWAP"},"data":[{"asks":[["84093.5","667.19","0","70"]],"bids":[["84093.4","570.26","0","83"]],"ts":"1790439594910","seqId":342177336961}]}
91951720090117	{"arg":{"channel":"bbo-tbt","instId":"BTC-USDT-SWAP"},"data":[{"asks":[["84093.5","667.28","0","71"]],"bids":[["84093.4","570.26","0","83"]],"ts":"1790439594950","seqId":342177336986}]}
91951736427349	{"arg":{"channel":"books","instId":"BTC-USDT-SWAP"},"action":"update","data":[{"asks":[["84093.5","667.28","0","71"],["84116.5","0.01","0","1"],["84118.6","0.03","0","1"],["84124.6","132.11","0","5"],["84126.7","12.07","0","2"],["84144.9","355.08","0","7"]],"bids":[["84093.4","570.26","0","83"],["84091","0.01","0","1"],["84079.5","11.9","0","1"],["84076.4","0","0","0"],["84071.5","0.01","0","1"],["84071.1","0.02","0","2"],["84071","209.99","0","2"],["84061.3","2.85","0","1"],["84056.1","0.01","0","1"],["84055.7","12.43","0","3"],["84055.3","0","0","0"],["84052.1","11.94","0","3"],["84044.9","109.5","0","5"],["84043.5","11.92","0","1"],["84043.4","2.85","0","2"],["84043.3","513.03","0","4"],["84041.7","38.96","0","4"],["84032","0","0","0"]],"ts":"1790439595000","checksum":0,"seqId":342177337045,"prevSeqId":342177336945}]}
91951771470304	{"arg":{"channel":"trades","instId":"BTC-USDT-SWAP"},"data":[{"instId":"BTC-USDT-SWAP","tradeId":"2953620210","px":"84093.4","sz":"0.1","side":"sell","ts":"1790439595038","count":"1","source":"0","seqId":342177337134}]}
91951772198214	{"arg":{"channel":"bbo-tbt","instId":"BTC-USDT-SWAP"},"data":[{"asks":[["84093.5","667.28","0","71"]],"bids":[["84093.4","570.16","0","83"]],"ts":"1790439595040","seqId":342177337138}]}
91951782250033	{"arg":{"channel":"bbo-tbt","instId":"BTC-USDT-SWAP"},"data":[{"asks":[["84093.5","667.28","0","71"]],"bids":[["84093.4","570.1","0","82"]],"ts":"1790439595050","seqId":342177337151}]}
91951791364379	{"arg":{"channel":"bbo-tbt","instId":"BTC-USDT-SWAP"},"data":[{"asks":[["84093.5","667.28","0","71"]],"bids":[["84093.4","570.15","0","83"]],"ts":"1790439595060","seqId":342177337166}]}
91951828061179	{"arg":{"channel":"books","instId":"BTC-USDT-SWAP"},"action":"update","data":[{"asks":[["84112.8","249.72","0","2"],["84113","0.01","0","1"],["84116.3","100.56","0","4"],["84118.5","427.29","0","7"],["84121.8","0.98","0","4"],["84122.2","0.01","0","1"]],"bids":[["84093.4","570.15","0","83"],["84080","237.94","0","4"],["84079.5","12.85","0","2"]],"ts":"1790439595100","checksum":0,"seqId":342177337200,"prevSeqId":342177337045}]}
91951907963970	{"arg":{"channel":"bbo-tbt","instId":"BTC-USDT-SWAP"},"data":[{"asks":[["84093.5","667.26","0","70"]],"bids":[["84093.4","570.15","0","83"]],"ts":"1790439595190","seqId":342177337301}]}
91951917771639	{"arg":{"channel":"books","instId":"BTC-USDT-SWAP"},"action":"update","data":[{"asks":[["84093.5","667.26","0","70"],["84100.4","0.12","0","3"],["84101.1","0.12","0","5"],["84101.8","0.11","0","2"],["84105.4","0.01","0","1"],["84106.4","0","0","0"],["84109.2","0.19","0","7"],["84112.3","0","0","0"],["84112.4","50.67","0","3"],["84113","0","0","0"],["84116","0","0","0"],["84119.4","0.05","0","3"],["84119.8","141.74","0","4"],["84124.4","0.12","0","1"],["84124.6","132.12","0","5"],["84126.7","12.06","0","2"],["84129.9","0.32","0","3"],["84138.2","0.01","0","1"],["84140.1","0.62","0","3"],["84141.8","0.01","0","1"],["84144.8","0.01","0","1"],["84144.9","355.07","0","6"],["84145.6","0","0","0"],["84147.7","0.01","0","1"]],"bids":[["84090","0.01","0","1"],["84089.9","0.48","0","4"],["84032.5","8.24","0","1"]],"ts":"1790439595200","checksum":0,"seqId":342177337312,"prevSeqId":342177337200}]}
91951927522035	{"arg":{"channel":"bbo-tbt","instId":"BTC-USDT-SWAP"},"data":[{"asks":[["84093.5","667.28","0","71"]],"bids":[["84093.4","570.15","0","83"]],"ts":"1790439595210","seqId":342177337316}]}
91951971457546	{"arg":{"channel":"bbo-tbt","instId":"BTC-USDT-SWAP"},"data":[{"asks":[["84093.5","667.27","0","71"]],"bids":[["84093.4","570.15","0","83"]],"ts":"1790439595260","seqId":342177337369}]}
91951997353584	{"arg":{"channel":"bbo-tbt","instId":"BTC-USDT-SWAP"},"data":[{"asks":[["84093.5","667.27","0","71"]],"bids":[["84093.4","545.87","0","82"]],"ts":"1790439595290","seqId":342177337415}]}
91952006680296	{"arg":{"channel":"bbo-tbt","instId":"BTC-USDT-SWAP"},"data":[{"asks":[["84093.5","667.27","0","71"]],"bids":[["84093.4","569.8","0","83"]],"ts":"1790439595300","seqId":342177337420}]}
91952006680296	{"arg":{"channel":"books","instId":"BTC-USDT-SWAP"},"action":"update","data":[{"asks":[["84093.5","667.27","0","71"],["84117.8","238.42","0","2"],["84119.2","12.04","0","4"],["84126.4","268.12","0","2"],["84129.4","0","0","0"],["84148.7","0.01","0","1"]],"bids":[["84093.4","569.8","0","83"]],"ts":"1790439595300","checksum":0,"seqId":342177337420,"prevSeqId":342177337312}]}
91952024237891	{"arg":{"channel":"bbo-tbt","instId":"BTC-USDT-SWAP"},"data":[{"asks":[["84093.5","667.27","0","71"]],"bids":[["84093.4","569.81","0","83"]],"ts":"1790439595320","seqId":342177337428}]}
91952096322907	{"arg":{"channel":"books","instId":"BTC-USDT-SWAP"},"action":"update","data":[{"asks":[["84117.8","0.01","0","1"],["84117.9","238.44","0","4"],["84124.6","132.13","0","5"],["84126.4","29.71","0","1"],["84126.5","238.44","0","4"],["84126.7","12.05","0","2"]],"bids":[["84093.4","569.81","0","83"]],"ts":"1790439595400","checksum":0,"seqId":342177337464,"prevSeqId":342177337420}]}
91952176869756	{"arg":{"channel":"bbo-tbt","instId":"BTC-USDT-SWAP"},"data":[{"asks":[["84093.5","667.27","0","71"]],"bids":[["84093.4","569.17","0","82"]],"ts":"1790439595490","seqId":342177337531}]}
91952186366584	{"arg":{"channel":"books","instId":"BTC-USDT-SWAP"},"action":"update","data":[{"asks":[],"bids":[["84093.4","569.17","0","82"]],"ts":"1790439595500","checksum":0,"seqId":342177337533,"prevSeqId":342177337464}]}
91952200028233	{"arg":{"channel":"bbo-tbt","instId":"BTC-USDT-SWAP"},"data":[{"asks":[["84093.5","667.27","0","71"]],"bids":[["84093.4","569.8","0","83"]],"ts":"1790439595510","seqId":342177337540}]}
91952212712722	{"arg":{"channel":"bbo-tbt","instId":"BTC-USDT-SWAP"},"data":[{"asks":[["84093.5","667.27","0","71"]],"bids":[["84093.4","564.27","0","82"]],"ts":"1790439595530","seqId":342177337574}]}
91952222168630	{"arg":{"channel":"bbo-tbt","instId":"BTC-USDT-SWAP"},"data":[{"asks":[["84093.5","667.27","0","71"]],"bids":[["84093.4","569.79","0","83"]],"ts":"1790439595540","seqId":342177337608}]}
91952248745429	{"arg":{"channel":"bbo-tbt","instId":"BTC-USDT-SWAP"},"data":[{"asks":[["84093.5","667.27","0","71"]],"bids":[["84093.4","569.78","0","83"]],"ts":"1790439595570","seqId":342177337635}]}
91952276293363	{"arg":{"channel":"books","instId":"BTC-USDT-SWAP"},"action":"update","data":[{"asks":[["84117.8","0.11","0","2"],["84124.6","132.14","0","5"],["84126.7","12.04","0","2"],["84127.9","0.01","0","1"]],"bids":[["84093.4","569.78","0","83"]],"ts":"1790439595600","checksum":0,"seqId":342177337650,"prevSeqId":342177337533}]}
91952347656530	{"arg":{"channel":"bbo-tbt","instId":"BTC-USDT-SWAP"},"data":[{"asks":[["84093.5","666.57","0","70"]],"bids":[["84093.4","569.78","0","83"]],"ts":"1790439595680","seqId":342177337703}]}
91952357724155	{"arg":{"channel":"bbo-tbt","instId":"BTC-USDT-SWAP"},"data":[{"asks":[["84093.5","666.53","0","69"]],"bids":[["84093.4","569.78","0","83"]],"ts":"1790439595690","seqId":342177337708}]}
91952366327483	{"arg":{"channel":"books","instId":"BTC-USDT-SWAP"},"action":"update","data":[{"asks":[["84093.5","666.53","0","69"],["84121.1","0","0","0"],["84121.3","2.4","0","4"],["84148.9","104.6","0","2"]],"bids":[["84079.6","265.71","0","4"],["84079.5","11.9","0","1"]],"ts":"1790439595700","checksum":0,"seqId":342177337711,"prevSeqId":342177337650}]}
91952393068226	{"arg":{"channel":"bbo-tbt","instId":"BTC-USDT-SWAP"},"data":[{"asks":[["84093.5","666.51","0","68"]],"bids":[["84093.4","569.78","0","83"]],"ts":"1790439595730","seqId":342177337739}]}
91952401908179	{"arg":{"channel":"bbo-tbt","instId":"BTC-USDT-SWAP"},"data":[{"asks":[["84093.5","666.54","0","69"]],"bids":[["84093.4","569.78","0","83"]],"ts":"1790439595740","seqId":342177337757}]}
91952411246884	{"arg":{"channel":"bbo-tbt","instId":"BTC-USDT-SWAP"},"data":[{"asks":[["84093.5","666.56","0","70"]],"bids":[["84093.4","569.78","0","83"]],"ts":"1790439595750","seqId":342177337760}]}
91952429244340	{"arg":{"channel":"bbo-tbt","instId":"BTC-USDT-SWAP"},"data":[{"asks":[["84093.5","666.56","0","70"]],"bids":[["84093.4","569.79","0","83"]],"ts":"1790439595770","seqId":342177337777}]}
91952456795074	{"arg":{"channel":"books","instId":"BTC-USDT-SWAP"},"action":"update","data":[{"asks":[["84093.5","666.56","0","70"],["84117.9","0.03","0","3"],["84124.6","132.15","0","5"],["84126.5","0.03","0","3"],["84126.7","12.03","0","2"]],"bids":[["84093.4","569.79","0","83"]],"ts":"1790439595800","checksum":0,"seqId":342177337822,"prevSeqId":342177337711}]}
91952478296131	{"arg":{"channel":"trades","instId":"BTC-USDT-SWAP"},"data":[{"instId":"BTC-USDT-SWAP","tradeId":"2953620211","px":"84093.4","sz":"0.04","side":"sell","ts":"1790439595824","count":"1","source":"0","seqId":342177337833}]}
91952482966782	{"arg":{"channel":"bbo-tbt","instId":"BTC-USDT-SWAP"},"data":[{"asks":[["84093.5","666.56","0","70"]],"bids":[["84093.4","569.75","0","83"]],"ts":"1790439595830","seqId":342177337839}]}
91952519157074	{"arg":{"channel":"bbo-tbt","instId":"BTC-USDT-SWAP"},"data":[{"asks":[["84093.5","663.52","0","69"]],"bids":[["84093.4","569.75","0","83"]],"ts":"1790439595870","seqId":342177337858}]}
91952527852989	{"arg":{"channel":"bbo-tbt","instId":"BTC-USDT-SWAP"},"data":[{"asks":[["84093.5","667.16","0","70"]],"bids":[["84093.4","569.75","0","83"]],"ts":"1790439595880","seqId":342177337865}]}
91952546310608	{"arg":{"channel":"books","instId":"BTC-USDT-SWAP"},"action":"update","data":[{"asks":[["84093.5","667.16","0","70"]],"bids":[["84093.4","569.75","0","83"]],"ts":"1790439595900","checksum":0,"seqId":342177337872,"prevSeqId":342177337822}]}
91952589158440	{"arg":{"channel":"trades","instId":"BTC-USDT-SWAP"},"data":[{"instId":"BTC-USDT-SWAP","tradeId":"2953620212","px":"84093.5","sz":"2.42","side":"buy","ts":"1790439595946","count":"1","source":"0","seqId":342177337897}]}
91952590948631	{"arg":{"channel":"bbo-tbt","instId":"BTC-USDT-SWAP"},"data":[{"asks":[["84093.5","664.74","0","70"]],"bids":[["84093.4","569.75","0","83"]],"ts":"1790439595950","seqId":342177337899}]}
91952626787989	{"arg":{"channel":"bbo-tbt","instId":"BTC-USDT-SWAP"},"data":[{"asks":[["84093.5","664.74","0","70"]],"bids":[["84093.4","569.64","0","83"]],"ts":"1790439595990","seqId":342177337964}]}
91952636536131	{"arg":{"channel":"books","instId":"BTC-USDT-SWAP"},"action":"update","data":[{"asks":[["84093.5","664.74","0","70"],["84102","161.79","0","9"],["84110.4","68.06","0","3"],["84121.3","0.03","0","3"],["84121.8","3.35","0","5"],["84124.6","132.16","0","5"],["84126.7","12.02","0","2"]],"bids":[["84093.4","569.64","0","83"],["84090.5","0","0","0"],["84086.6","0.04","0","4"],["84085.9","0","0","0"],["84083.2","0.03","0","3"],["84081.9","0","0","0"],["84071.1","2.39","0","3"],["84069.5","0.01","0","1"],["84053.5","0.01","0","1"],["84032","0.04","0","4"],["84031.7","0.01","0","1"]],"ts":"1790439596000","checksum":0,"seqId":342177337968,"prevSeqId":342177337872}]}
91952727025260	{"arg":{"channel":"books","instId":"BTC-USDT-SWAP"},"action":"update","data":[{"asks":[["84109.8","904.56","0","2"],["84110","2535.3","0","126"],["84121.1","2.37","0","1"],["84121.8","0.98","0","4"],["84148.9","0","0","0"]],"bids":[["84088.5","12.86","0","2"],["84088.1","0","0","0"],["84079.6","264.74","0","2"],["84079.5","12.87","0","3"],["84076.2","1.14","0","5"],["84076","0.02","0","1"],["84075.4","0.01","0","1"],["84075","2.59","0","3"],["84071.8","0","0","0"],["84071.1","0.02","0","2"],["84069.5","2.38","0","2"],["84059.4","0.12","0","1"],["84055","0.03","0","3"],["84049.8","0.02","0","1"],["84046.5","5.72","0","2"],["84031.7","0","0","0"]],"ts":"1790439596100","checksum":0,"seqId":342177338162,"prevSeqId":342177337968}]}
91952745883253	{"arg":{"channel":"bbo-tbt","instId":"BTC-USDT-SWAP"},"data":[{"asks":[["84093.5","664.74","0","70"]],"bids":[["84093.4","567.77","0","82"]],"ts":"1790439596120","seqId":342177338183}]}
91952816629200	{"arg":{"channel":"books","instId":"BTC-USDT-SWAP"},"action":"update","data":[{"asks":[["84110.3","0.02","0","2"],["84112.4","50.66","0","2"],["84112.7","0.01","0","1"],["84113.9","0.01","0","1"],["84114.5","67.02","0","2"],["84114.9","0.01","0","1"],["84119.4","0.04","0","2"],["84124.6","132.17","0","5"],["84126.7","12.01","0","2"],["84129.9","0.33","0","4"],["84138.2","0","0","0"],["84147.7","0","0","0"]],"bids":[["84093.4","567.77","0","82"],["84088.5","12.84","0","1"],["84088.4","0.02","0","1"],["84079.6","264.72","0","1"],["84079.5","12.89","0","4"],["84049.8","0","0","0"],["84047.2","1.34","0","3"]],"ts":"1790439596200","checksum":0,"seqId":342177338231,"prevSeqId":342177338162}]}
91952825584807	{"arg":{"channel":"bbo-tbt","instId":"BTC-USDT-SWAP"},"data":[{"asks":[["84093.5","664.74","0","70"]],"bids":[["84093.4","567.79","0","82"]],"ts":"1790439596210","seqId":342177338235}]}
91952871435840	{"arg":{"channel":"bbo-tbt","instId":"BTC-USDT-SWAP"},"data":[{"asks":[["84093.5","664.72","0","69"]],"bids":[["84093.4","567.79","0","82"]],"ts":"1790439596260","seqId":342177338339}]}
91952885981929	{"arg":{"channel":"trades","instId":"BTC-USDT-SWAP"},"data":[{"instId":"BTC-USDT-SWAP","tradeId":"2953620213","px":"84093.4","sz":"0.7","side":"sell","ts":"1790439596276","count":"1","source":"0","seqId":342177338362}]}
91952889653833	{"arg":{"channel":"bbo-tbt","instId":"BTC-USDT-SWAP"},"data":[{"asks":[["84093.5","664.74","0","70"]],"bids":[["84093.4","567.09","0","82"]],"ts":"1790439596280","seqId":342177338367}]}
91952908033695	{"arg":{"channel":"bbo-tbt","instId":"BTC-USDT-SWAP"},"data":[{"asks":[["84093.5","623.44","0","68"]],"bids":[["84093.4","567.09","0","82"]],"ts":"1790439596300","seqId":342177338411}]}
91952908033695	{"arg":{"channel":"books","instId":"BTC-USDT-SWAP"},"action":"update","data":[{"asks":[["84093.5","623.44","0","68"],["84097.8","0.03","0","3"],["84105.5","0","0","0"],["84110.4","1.04","0","2"],["84140.2","0.03","0","3"],["84148.9","104.6","0","2"]],"bids":[["84093.4","567.09","0","82"]],"ts":"1790439596300","checksum":0,"seqId":342177338411,"prevSeqId":342177338231}]}
91952916424371	{"arg":{"channel":"bbo-tbt","instId":"BTC-USDT-SWAP"},"data":[{"asks":[["84093.5","623.44","0","68"]],"bids":[["84093.4","567.11","0","82"]],"ts":"1790439596310","seqId":342177338475}]}
91952952644988	{"arg":{"channel":"bbo-tbt","instId":"BTC-USDT-SWAP"},"data":[{"asks":[["84093.5","623.44","0","68"]],"bids":[["84093.4","567.04","0","81"]],"ts":"1790439596350","seqId":342177338509}]}
91952964033468	{"arg":{"channel":"bbo-tbt","instId":"BTC-USDT-SWAP"},"data":[{"asks":[["84093.5","623.44","0","68"]],"bids":[["84093.4","567.1","0","82"]],"ts":"1790439596360","seqId":342177338512}]}
91952999151994	{"arg":{"channel":"books","instId":"BTC-USDT-SWAP"},"action":"update","data":[{"asks":[["84102","228.81","0","10"],["84112.5","70.25","0","5"],["84112.7","0.02","0","2"],["84121.7","0.97","0","3"],["84121.8","0.03","0","3"],["84143.3","139.97","0","1"],["84148.9","0","0","0"]],"bids":[["84093.4","567.1","0","82"],["84090.1","17.57","0","3"],["84089.9","0.02","0","2"],["84088.4","0","0","0"],["84088.1","0.02","0","1"],["84079.6","264.74","0","2"],["84079.5","12.87","0","3"],["84047.9","0.02","0","1"],["84047.2","1.32","0","2"],["84032","0","0","0"]],"ts":"1790439596400","checksum":0,"seqId":342177338529,"prevSeqId":342177338411}]}
91953053003158	{"arg":{"channel":"trades","instId":"BTC-USDT-SWAP"},"data":[{"instId":"BTC-USDT-SWAP","tradeId":"2953620214","px":"84093.5","sz":"0.01","side":"buy","ts":"1790439596458","count":"1","source":"0","seqId":342177338557}]}
91953060034603	{"arg":{"channel":"bbo-tbt","instId":"BTC-USDT-SWAP"},"data":[{"asks":[["84093.5","623.43","0","68"]],"bids":[["84093.4","567.1","0","82"]],"ts":"1790439596460","seqId":342177338563}]}
91953074182904	{"arg":{"channel":"bbo-tbt","instId":"BTC-USDT-SWAP"},"data":[{"asks":[["84093.5","623.43","0","68"]],"bids":[["84093.4","567.17","0","82"]],"ts":"1790439596480","seqId":342177338569}]}
91953080866943	{"arg":{"channel":"bbo-tbt","instId":"BTC-USDT-SWAP"},"data":[{"asks":[["84093.5","623.41","0","67"]],"bids":[["84093.4","567.17","0","82"]],"ts":"1790439596490","seqId":342177338601}]}
91953091250139	{"arg":{"channel":"bbo-tbt","instId":"BTC-USDT-SWAP"},"data":[{"asks":[["84093.5","623.45","0","68"]],"bids":[["84093.4","567.14","0","81"]],"ts":"1790439596500","seqId":342177338613}]}
91953091250139	{"arg":{"channel":"books","instId":"BTC-USDT-SWAP"},"action":"update","data":[{"asks":[["84093.5","623.45","0","68"],["84097.7","0.01","0","1"],["84099.6","0.02","0","2"],["84099.9","2.42","0","6"],["84101.9","0.02","0","2"],["84112.7","0.01","0","1"],["84112.9","3.01","0","2"],["84118.7","44.25","0","5"],["84124.6","132.18","0","5"],["84126.4","0","0","0"],["84126.7","12","0","2"],["84131.9","0.01","0","1"],["84135.2","0.01","0","1"],["84136.1","289.72","0","3"]],"bids":[["84093.4","567.14","0","81"],["84088.4","0.02","0","1"],["84088.1","0","0","0"],["84049.8","0.02","0","1"],["84047.9","0","0","0"]],"ts":"1790439596500","checksum":0,"seqId":342177338613,"prevSeqId":342177338529}]}
91953098855582	{"arg":{"channel":"bbo-tbt","instId":"BTC-USDT-SWAP"},"data":[{"asks":[["84093.5","350.74","0","65"]],"bids":[["84093.4","658.98","0","82"]],"ts":"1790439596510","seqId":342177338628}]}
91953100088268	{"arg":{"channel":"trades","instId":"BTC-USDT-SWAP"},"data":[{"instId":"BTC-USDT-SWAP","tradeId":"2953620215","px":"84093.5","sz":"4.32","side":"buy","ts":"1790439596511","count":"1","source":"0","seqId":342177338647}]}
91953100088268	{"arg":{"channel":"trades","instId":"BTC-USDT-SWAP"},"data":[{"instId":"BTC-USDT-SWAP","tradeId":"2953620216","px":"84093.5","sz":"11.31","side":"buy","ts":"1790439596511","count":"1","source":"0","seqId":342177338649}]}
91953100088268	{"arg":{"channel":"trades","instId":"BTC-USDT-SWAP"},"data":[{"instId":"BTC-USDT-SWAP","tradeId":"2953620217","px":"84093.5","sz":"9.48","side":"buy","ts":"1790439596511","count":"1","source":"0","seqId":342177338651}]}
91953100088268	{"arg":{"channel":"trades","instId":"BTC-USDT-SWAP"},"data":[{"instId":"BTC-USDT-SWAP","tradeId":"2953620218","px":"84093.5","sz":"17.95","side":"buy","ts":"1790439596511","count":"1","source":"0","seqId":342177338654}]}
91953100088268	{"arg":{"channel":"trades","instId":"BTC-USDT-SWAP"},"data":[{"instId":"BTC-USDT-SWAP","tradeId":"2953620219","px":"84093.5","sz":"11.58","side":"buy","ts":"1790439596511","count":"1","source":"0","seqId":342177338656}]}
91953101871418	{"arg":{"channel":"trades","instId":"BTC-USDT-SWAP"},"data":[{"instId":"BTC-USDT-SWAP","tradeId":"2953620220","px":"84093.5","sz":"4","side":"buy","ts":"1790439596513","count":"1","source":"0","seqId":342177338704}]}
91953107667350	{"arg":{"channel":"bbo-tbt","instId":"BTC-USDT-SWAP"},"data":[{"asks":[["84093.5","28.31","0","59"]],"bids":[["84093.4","771.75","0","87"]],"ts":"1790439596520","seqId":342177338886}]}
91953108156616	{"arg":{"channel":"trades","instId":"BTC-USDT-SWAP"},"data":[{"instId":"BTC-USDT-SWAP","tradeId":"2953620221","px":"84093.5","sz":"4","side":"buy","ts":"1790439596520","count":"1","source":"0","seqId":342177338906}]}
91953109219702	{"arg":{"channel":"trades","instId":"BTC-USDT-SWAP"},"data":[{"instId":"BTC-USDT-SWAP","tradeId":"2953620280","px":"84093.5","sz":"24.31","side":"buy","ts":"1790439596521","count":"59","source":"0","seqId":342177339042}]}
91953109219702	{"arg":{"channel":"trades","instId":"BTC-USDT-SWAP"},"data":[{"instId":"BTC-USDT-SWAP","tradeId":"2953620281","px":"84093.6","sz":"0.51","side":"buy","ts":"1790439596521","count":"1","source":"0","seqId":342177339042}]}
91953109896819	{"arg":{"channel":"trades","instId":"BTC-USDT-SWAP"},"data":[{"instId":"BTC-USDT-SWAP","tradeId":"2953620282","px":"84094","sz":"0.01","side":"buy","ts":"1790439596522","count":"1","source":"0","seqId":342177339145}]}
91953109896819	{"arg":{"channel":"trades","instId":"BTC-USDT-SWAP"},"data":[{"instId":"BTC-USDT-SWAP","tradeId":"2953620284","px":"84094.1","sz":"0.02","side":"buy","ts":"1790439596522","count":"2","source":"0","seqId":342177339145}]}
91953109896819	{"arg":{"channel":"trades","instId":"BTC-USDT-SWAP"},"data":[{"instId":"BTC-USDT-SWAP","tradeId":"2953620286","px":"84094.4","sz":"0.02","side":"buy","ts":"1790439596522","count":"2","source":"0","seqId":342177339145}]}
91953109896819	{"arg":{"channel":"trades","instId":"BTC-USDT-SWAP"},"data":[{"instId":"BTC-USDT-SWAP","tradeId":"2953620287","px":"84095.1","sz":"0.01","side":"buy","ts":"1790439596522","count":"1","source":"0","seqId":342177339145}]}
91953109896819	{"arg":{"channel":"trades","instId":"BTC-USDT-SWAP"},"data":[{"instId":"BTC-USDT-SWAP","tradeId":"2953620288","px":"84095.2","sz":"0.05","side":"buy","ts":"1790439596522","count":"1","source":"0","seqId":342177339145}]}
91953109896819	{"arg":{"channel":"trades","instId":"BTC-USDT-SWAP"},"data":[{"instId":"BTC-USDT-SWAP","tradeId":"2953620291","px":"84095.5","sz":"0.03","side":"buy","ts":"1790439596522","count":"3","source":"0","seqId":342177339145}]}
91953114359198	{"arg":{"channel":"trades","instId":"BTC-USDT-SWAP"},"data":[{"instId":"BTC-USDT-SWAP","tradeId":"2953620292","px":"84095.6","sz":"9.51","side":"buy","ts":"1790439596527","count":"1","source":"0","seqId":342177339666}]}
91953116963422	{"arg":{"channel":"bbo-tbt","instId":"BTC-USDT-SWAP"},"data":[{"asks":[["84095.6","51.51","0","3"]],"bids":[["84095.5","2017.97","0","63"]],"ts":"1790439596530","seqId":342177339774}]}
91953132033751	{"arg":{"channel":"bbo-tbt","instId":"BTC-USDT-SWAP"},"data":[{"asks":[["84095.6","51.67","0","6"]],"bids":[["84095.5","2028.06","0","67"]],"ts":"1790439596540","seqId":342177340036}]}
91953134791439	{"arg":{"channel":"bbo-tbt","instId":"BTC-USDT-SWAP"},"data":[{"asks":[["84095.6","51.67","0","6"]],"bids":[["84095.5","2151.43","0","72"]],"ts":"1790439596550","seqId":342177340135}]}
91953135904127	{"arg":{"channel":"trades","instId":"BTC-USDT-SWAP"},"data":[{"instId":"BTC-USDT-SWAP","tradeId":"2953620298","px":"84095.6","sz":"51.67","side":"buy","ts":"1790439596551","count":"6","source":"0","seqId":342177340166}]}
91953137343527	{"arg":{"channel":"trades","instId":"BTC-USDT-SWAP"},"data":[{"instId":"BTC-USDT-SWAP","tradeId":"2953620299","px":"84095.8","sz":"0.01","side":"buy","ts":"1790439596552","count":"1","source":"0","seqId":342177340224}]}
91953137343527	{"arg":{"channel":"trades","instId":"BTC-USDT-SWAP"},"data":[{"instId":"BTC-USDT-SWAP","tradeId":"2953620300","px":"84095.9","sz":"0.01","side":"buy","ts":"1790439596552","count":"1","source":"0","seqId":342177340224}]}
91953137343527	{"arg":{"channel":"trades","instId":"BTC-USDT-SWAP"},"data":[{"instId":"BTC-USDT-SWAP","tradeId":"2953620301","px":"84096","sz":"0.01","side":"buy","ts":"1790439596552","count":"1","source":"0","seqId":342177340224}]}
91953137343527	{"arg":{"channel":"trades","instId":"BTC-USDT-SWAP"},"data":[{"instId":"BTC-USDT-SWAP","tradeId":"2953620302","px":"84096.6","sz":"0.01","side":"buy","ts":"1790439596552","count":"1","source":"0","seqId":342177340224}]}
91953137343527	{"arg":{"channel":"trades","instId":"BTC-USDT-SWAP"},"data":[{"instId":"BTC-USDT-SWAP","tradeId":"2953620303","px":"84096.8","sz":"0.01","side":"buy","ts":"1790439596552","count":"1","source":"0","seqId":342177340224}]}
91953137343527	{"arg":{"channel":"trades","instId":"BTC-USDT-SWAP"},"data":[{"instId":"BTC-USDT-SWAP","tradeId":"2953620304","px":"84097.7","sz":"0.01","side":"buy","ts":"1790439596552","count":"1","source":"0","seqId":342177340224}]}
91953137343527	{"arg":{"channel":"trades","instId":"BTC-USDT-SWAP"},"data":[{"instId":"BTC-USDT-SWAP","tradeId":"2953620305","px":"84097.8","sz":"0.01","side":"buy","ts":"1790439596552","count":"1","source":"0","seqId":342177340224}]}
91953137343527	{"arg":{"channel":"trades","instId":"BTC-USDT-SWAP"},"data":[{"instId":"BTC-USDT-SWAP","tradeId":"2953620307","px":"84097.9","sz":"0.11","side":"buy","ts":"1790439596552","count":"2","source":"0","seqId":342177340224}]}
91953137343527	{"arg":{"channel":"trades","instId":"BTC-USDT-SWAP"},"data":[{"instId":"BTC-USDT-SWAP","tradeId":"2953620309","px":"84098.1","sz":"0.11","side":"buy","ts":"1790439596552","count":"2","source":"0","seqId":342177340224}]}
91953137343527	{"arg":{"channel":"trades","instId":"BTC-USDT-SWAP"},"data":[{"instId":"BTC-USDT-SWAP","tradeId":"2953620310","px":"84098.7","sz":"0.01","side":"buy","ts":"1790439596552","count":"1","source":"0","seqId":342177340224}]}
91953137343527	{"arg":{"channel":"trades","instId":"BTC-USDT-SWAP"},"data":[{"instId":"BTC-USDT-SWAP","tradeId":"2953620312","px":"84099.2","sz":"0.02","side":"buy","ts":"1790439596552","count":"2","source":"0","seqId":342177340224}]}
91953137343527	{"arg":{"channel":"trades","instId":"BTC-USDT-SWAP"},"data":[{"instId":"BTC-USDT-SWAP","tradeId":"2953620314","px":"84099.5","sz":"0.02","side":"buy","ts":"1790439596552","count":"2","source":"0","seqId":342177340224}]}
91953143921815	{"arg":{"channel":"bbo-tbt","instId":"BTC-USDT-SWAP"},"data":[{"asks":[["84099.6","309.39","0","10"]],"bids":[["84099.5","1738.73","0","41"]],"ts":"1790439596560","seqId":342177340839}]}
91953148581002	{"arg":{"channel":"trades","instId":"BTC-USDT-SWAP"},"data":[{"instId":"BTC-USDT-SWAP","tradeId":"2953620315","px":"84099.5","sz":"2.55","side":"sell","ts":"1790439596564","count":"1","source":"0","seqId":342177340988}]}
91953154830574	{"arg":{"channel":"bbo-tbt","instId":"BTC-USDT-SWAP"},"data":[{"asks":[["84099.6","309.46","0","13"]],"bids":[["84099.5","1633","0","46"]],"ts":"1790439596570","seqId":342177341063}]}
91953171101263	{"arg":{"channel":"bbo-tbt","instId":"BTC-USDT-SWAP"},"data":[{"asks":[["84099.6","309.46","0","13"]],"bids":[["84099.5","1652.89","0","48"]],"ts":"1790439596590","seqId":342177341200}]}
91953182506088	{"arg":{"channel":"books","instId":"BTC-USDT-SWAP"},"action":"update","data":[{"asks":[["84093.5","0","0","0"],["84093.6","0","0","0"],["84094","0","0","0"],["84094.1","0","0","0"],["84094.4","0","0","0"],["84095.1","0","0","0"],["84095.2","0","0","0"],["84095.5","0","0","0"],["84095.6","0","0","0"],["84095.8","0","0","0"],["84095.9","0","0","0"],["84096","0","0","0"],["84096.3","0","0","0"],["84096.6","0","0","0"],["84096.8","0","0","0"],["84097","0","0","0"],["84097.1","0","0","0"],["84097.7","0","0","0"],["84097.8","0","0","0"],["84097.9","0","0","0"],["84098.1","0","0","0"],["84098.2","0","0","0"],["84098.7","0","0","0"],["84099","0","0","0"],["84099.2","0","0","0"],["84099.5","0","0","0"],["84099.6","309.46","0","13"],["84099.7","0.02","0","2"],["84099.8","0.01","0","1"],["84099.9","0.02","0","2"],["84100.4","0.02","0","2"],["84100.5","0","0","0"],["84100.9","0.03","0","3"],["84101.1","0.05","0","5"],["84101.6","0.01","0","1"],["84101.8","0","0","0"],["84101.9","0.13","0","4"],["84102","46.53","0","5"],["84102.2","0","0","0"],["84102.5","0.01","0","1"],["84102.6","0.01","0","1"],["84102.7","0.01","0","1"],["84102.8","0","0","0"],["84103.2","0.01","0","1"],["84103.6","0.02","0","2"],["84103.8","0.02","0","2"],["84103.9","6.51","0","1"],["84104","0.03","0","3"],["84104.2","0.11","0","2"],["84104.3","0","0","0"],["84104.6","0.02","0","2"],["84104.7","0","0","0"],["84105","0.03","0","3"],["84105.6","0.1","0","3"],["84106.3","6","0","1"],["84106.4","0.1","0","1"],["84106.5","0.11","0","2"],["84106.9","0","0","0"],["84107.5","0","0","0"],["84108","1.21","0","4"],["84108.1","0.12","0","1"],["84108.5","1.09","0","4"],["84108.7","0","0","0"],["84108.8","0.11","0","2"],["84109","0","0","0"],["84109.3","0.05","0","3"],["84109.5","1.22","0","2"],["84109.6","2.47","0","2"],["84109.7","28.67","0","7"],["84109.8","899.88","0","1"],["84109.9","0.03","0","3"],["84110.1","0.03","0","3"],["84110.2","0.01","0","1"],["84110.4","1.05","0","3"],["84110.5","0","0","0"],["84111.1","0.13","0","2"],["84112.1","2.1","0","2"],["84112.4","0.01","0","1"],["84112.5","0.05","0","4"],["84112.6","0.01","0","1"],["84112.8","1.42","0","1"],["84112.9","0","0","0"],["84113.4","228.99","0","4"],["84113.5","167.82","0","3"],["84113.6","22","0","2"],["84114","0.01","0","1"],["84114.6","0.03","0","3"],["84114.9","4.72","0","2"],["84115","4.57","0","1"],["84115.6","8.39","0","1"],["84115.7","0.01","0","1"],["84116.1","0","0","0"],["84116.3","100.7","0","4"],["84116.4","2.6","0","1"],["84116.7","0","0","0"],["84116.9","0.12","0","2"],["84117.1","0","0","0"],["84117.5","11.89","0","1"],["84117.8","0.01","0","1"],["84118","334.73","0","2"],["84118.2","0.75","0","1"],["84118.5","207.4","0","6"],["84118.7","14.54","0","4"],["84118.8","5.37","0","1"],["84118.9","11.92","0","2"],["84119.2","209.84","0","3"],["84119.3","357.52","0","4"],["84119.5","0.16","0","2"],["84120","0.83","0","14"],["84120.1","50.23","0","3"],["84120.7","2.38","0","2"],["84120.8","220.63","0","1"],["84121.1","0","0","0"],["84121.2","0.58","0","1"],["84121.3","59.61","0","4"],["84121.4","0.11","0","1"],["84121.7","47.68","0","3"],["84121.9","0","0","0"],["84122.3","0","0","0"],["84122.6","117.84","0","1"],["84122.7","98.54","0","4"],["84123.1","0.37","0","1"],["84123.2","29.72","0","2"],["84123.4","0.5","0","1"],["84124.5","12.51","0","3"],["84125.7","41.81","0","5"],["84126","0.12","0","5"],["84126.1","46.44","0","5"],["84126.5","38.81","0","5"],["84126.7","56.68","0","3"],["84127","17.35","0","3"],["84127.1","0.01","0","1"],["84127.6","2.56","0","1"],["84127.7","0","0","0"],["84128.1","2.64","0","2"],["84128.3","1.3","0","5"],["84129.7","45.27","0","2"],["84130.9","0","0","0"],["84131.2","0.01","0","1"],["84131.7","177.27","0","3"],["84132","12.32","0","4"],["84133.1","0","0","0"],["84135.2","0","0","0"],["84135.3","0","0","0"],["84135.5","12.65","0","3"],["84136.1","286.36","0","2"],["84136.2","61.03","0","3"],["84137.5","14.8","0","3"],["84138.3","48.42","0","4"],["84138.6","12.77","0","16"],["84138.9","0","0","0"],["84139.6","3.2","0","3"],["84139.7","11.92","0","1"],["84140.8","11.93","0","2"],["84141","2.86","0","2"],["84141.6","11.92","0","1"],["84142.4","14.77","0","2"],["84142.6","25.92","0","2"],["84143.2","12.82","0","2"],["84143.5","0.07","0","3"],["84144","23.66","0","9"],["84145","5.01","0","2"],["84145.3","0","0","0"],["84145.5","0","0","0"],["84147","0.03","0","3"],["84147.3","3.52","0","1"],["84148.9","107.37","0","3"],["84149","35.81","0","4"],["84149.1","74.28","0","3"],["84149.2","0.59","0","1"],["84149.3","35.78","0","2"],["84149.4","206.66","0","1"],["84149.5","89.25","0","2"],["84149.7","0.01","0","1"],["84149.8","0.5","0","1"],["84149.9","0.01","0","1"],["84150","240.94","0","53"],["84150.1","0.04","0","1"],["84150.2","0.1","0","1"],["84150.3","0.01","0","1"],["84150.4","0.02","0","2"],["84150.6","0.01","0","1"],["84150.7","0.01","0","1"],["84150.8","0.01","0","1"],["84151","4.36","0","5"],["84151.1","0.04","0","4"],["84151.2","0.01","0","1"],["84151.3","0.02","0","1"],["84151.5","0.03","0","2"],["84151.6","0.06","0","6"],["84151.7","6.08","0","2"],["84151.8","2.76","0","2"],["84151.9","0.02","0","1"],["84152","55.42","0","1"],["84152.3","2.39","0","2"],["84152.4","0.01","0","1"],["84152.5","0.04","0","4"],["84152.6","2.58","0","3"],["84152.7","0.04","0","2"],["84152.8","10.03","0","1"],["84152.9","0.04","0","2"],["84153","0.12","0","3"],["84153.3","1.19","0","12"],["84153.4","0.01","0","1"],["84153.5","0.02","0","1"],["84153.6","1.19","0","4"]],"bids":[["84099.5","1652.89","0","48"],["84099.4","47.78","0","4"],["84099.1","0.02","0","1"],["84099","0.01","0","1"],["84097.2","0.01","0","1"],["84097.1","0.46","0","2"],["84097","0.01","0","1"],["84096.9","0.1","0","1"],["84096.6","0.02","0","2"],["84096.5","0.01","0","1"],["84096","0.01","0","1"],["84095.9","0.02","0","2"],["84095.8","35.32","0","5"],["84095.7","217.86","0","7"],["84095.6","10.75","0","3"],["84095.5","37.63","0","8"],["84095.2","0.02","0","1"],["84094.6","0.01","0","1"],["84094.5","0.02","0","2"],["84094.4","0.01","0","1"],["84094.3","0.1","0","1"],["84094","0.01","0","1"],["84093.9","30.3","0","5"],["84093.7","0.02","0","2"],["84093.6","70.81","0","2"],["84093.5","0.02","0","2"],["84093.4","446.87","0","56"],["84093.3","0.11","0","2"],["84093.2","0.06","0","1"],["84093","0.08","0","3"],["84092.9","0.01","0","1"],["84092.8","0.01","0","1"],["84092.4","111.31","0","4"],["84092.3","221.89","0","2"],["84092.2","0","0","0"],["84092.1","0","0","0"],["84091.9","0.01","0","1"],["84091.7","0.1","0","1"],["84091.4","0.01","0","1"],["84091.3","0.01","0","1"],["84091.1","0.02","0","2"],["84091","169.59","0","4"],["84090.8","0","0","0"],["84090.4","0","0","0"],["84090.3","0.61","0","2"],["84090.2","0.01","0","1"],["84090.1","17.11","0","1"],["84089.9","0","0","0"],["84089.8","0.71","0","2"],["84089.7","0","0","0"],["84089.5","0.03","0","2"],["84089.4","0.01","0","1"],["84089.2","0.02","0","2"],["84089.1","70.96","0","3"],["84089","0.02","0","2"],["84088.9","114.99","0","3"],["84088.8","0","0","0"],["84088.7","11.93","0","1"],["84088.6","0.01","0","1"],["84088.4","0","0","0"],["84088.3","0.01","0","1"],["84088.2","144.06","0","3"],["84088","0.01","0","1"],["84087.9","0.13","0","4"],["84087.8","4.59","0","3"],["84086.6","0.03","0","3"],["84086.5","8.31","0","1"],["84086.2","10.05","0","2"],["84085.9","1.68","0","3"],["84085.8","38.09","0","5"],["84085.6","0","0","0"],["84085.2","10.61","0","3"],["84085","0","0","0"],["84084.9","2.59","0","2"],["84084.4","0.03","0","3"],["84084.3","0","0","0"],["84084.2","2.39","0","3"],["84084","244.72","0","8"],["84083.5","0","0","0"],["84083.3","0.02","0","1"],["84083","0","0","0"],["84082.1","0.59","0","1"],["84081.3","0.11","0","2"],["84081.2","2.37","0","1"],["84081.1","0.02","0","1"],["84080.9","8.31","0","1"],["84080.6","14.01","0","2"],["84080.1","0","0","0"],["84080","0.08","0","4"],["84079.9","56.71","0","3"],["84079.8","67.05","0","4"],["84079.7","0.01","0","1"],["84079.6","264.72","0","1"],["84079.5","11.93","0","3"],["84078.7","0.11","0","2"],["84078.4","0","0","0"],["84078","3.01","0","2"],["84077.2","2.42","0","3"],["84076.6","0.01","0","1"],["84076.5","1.11","0","2"],["84076.2","0.03","0","3"],["84075.2","0.01","0","1"],["84075","2.57","0","2"],["84074.6","0.01","0","1"],["84074.5","0.01","0","1"],["84074","11.92","0","1"],["84073.7","0","0","0"],["84073.1","0","0","0"],["84071.4","10.77","0","5"],["84071.2","0.84","0","1"],["84069.7","11.92","0","1"],["84069.5","0.02","0","2"],["84069.2","1.28","0","1"],["84068.9","0","0","0"],["84068.4","44.73","0","5"],["84066.3","0","0","0"],["84065.6","11.92","0","1"],["84065.5","5.94","0","4"],["84065.3","11.92","0","1"],["84065","23.85","0","3"],["84064.9","0.01","0","1"],["84064.8","0.23","0","2"],["84064.7","14.49","0","3"],["84064.4","11.92","0","1"],["84064.3","17.58","0","2"],["84064.1","60.53","0","4"],["84063.8","11.92","0","1"],["84063.4","11.92","0","1"],["84063","383.92","0","7"],["84062.6","11.93","0","2"],["84062.2","12.42","0","2"],["84061.8","12.68","0","3"],["84061.5","11.92","0","1"],["84061.3","2.86","0","2"],["84061","11.92","0","1"],["84060.7","12.43","0","3"],["84060.5","11.92","0","1"],["84060","14.79","0","4"],["84059.7","135.17","0","4"],["84059.4","0","0","0"],["84058.4","0.02","0","2"],["84058.1","0","0","0"],["84057.8","0.01","0","1"],["84057.5","0.02","0","2"],["84057.2","0","0","0"],["84056.9","5.74","0","4"],["84056.6","0","0","0"],["84056.3","1.19","0","1"],["84056","138.71","0","1"],["84055.7","0.5","0","1"],["84055.4","0.01","0","1"],["84055.1","0","0","0"],["84054.8","0.01","0","1"],["84054.6","224.82","0","2"],["84054.5","0.02","0","1"],["84054.2","0.01","0","1"],["84053.9","0","0","0"],["84053.6","2.88","0","4"],["84053.4","50.87","0","2"],["84052.6","0","0","0"],["84052.4","44.67","0","1"],["84050.4","0.01","0","1"],["84050.3","1.18","0","1"],["84050","26.28","0","24"],["84049.8","0","0","0"],["84049.6","0","0","0"],["84047.4","0.03","0","3"],["84047.3","0.01","0","1"],["84045.5","6.7","0","3"],["84045","0.05","0","4"],["84044.9","109.49","0","4"],["84043.4","0.01","0","1"],["84042.4","0","0","0"],["84039","0","0","0"],["84038.3","0.61","0","2"],["84037.8","2.57","0","2"],["84036.7","18.28","0","1"],["84036","8.45","0","1"],["84035.9","0","0","0"],["84035.6","0","0","0"],["84035.5","0","0","0"],["84035.4","0","0","0"],["84035.3","0","0","0"],["84035.2","0","0","0"],["84034.9","0","0","0"],["84034.8","0","0","0"],["84034.5","0","0","0"],["84034.2","0","0","0"],["84034","0","0","0"],["84033.8","0","0","0"],["84033.7","0","0","0"],["84033.6","0","0","0"],["84033.3","0","0","0"],["84033","0","0","0"],["84032.8","0","0","0"],["84032.5","0","0","0"]],"ts":"1790439596600","checksum":0,"seqId":342177341229,"prevSeqId":342177338613}]}
91953194962941	{"arg":{"channel":"bbo-tbt","instId":"BTC-USDT-SWAP"},"data":[{"asks":[["84099.6","309.46","0","13"]],"bids":[["84099.5","1674.29","0","49"]],"ts":"1790439596610","seqId":342177341513}]}
91953200077089	{"arg":{"channel":"bbo-tbt","instId":"BTC-USDT-SWAP"},"data":[{"asks":[["84099.6","309.48","0","14"]],"bids":[["84099.5","1674.33","0","51"]],"ts":"1790439596620","seqId":342177341567}]}
91953217522871	{"arg":{"channel":"bbo-tbt","instId":"BTC-USDT-SWAP"},"data":[{"asks":[["84099.6","185.53","0","12"]],"bids":[["84099.5","1689.3","0","52"]],"ts":"1790439596640","seqId":342177341684}]}
91953244359192	{"arg":{"channel":"bbo-tbt","instId":"BTC-USDT-SWAP"},"data":[{"asks":[["84099.6","185.54","0","13"]],"bids":[["84099.5","1689.3","0","52"]],"ts":"1790439596670","seqId":342177341759}]}
91953255652935	{"arg":{"channel":"bbo-tbt","instId":"BTC-USDT-SWAP"},"data":[{"asks":[["84099.6","316.47","0","15"]],"bids":[["84099.5","1684.71","0","53"]],"ts":"1790439596680","seqId":342177341783}]}
91953274396007	{"arg":{"channel":"books","instId":"BTC-USDT-SWAP"},"action":"update","data":[{"asks":[["84099.6","316.47","0","15"],["84100.8","0.01","0","1"],["84104.8","0","0","0"],["84105","0.01","0","1"],["84107.4","0.16","0","3"],["84108.1","12.57","0","2"],["84109.2","0.17","0","5"],["84113.4","228.98","0","3"],["84113.5","0.24","0","2"],["84114","4.68","0","2"],["84114.5","68.02","0","3"],["84116.3","91.41","0","3"],["84116.4","0","0","0"],["84116.5","169.79","0","4"],["84117.6","0.02","0","2"],["84118","337.1","0","3"],["84118.5","201.32","0","5"],["84119.2","209.83","0","2"],["84119.4","0.05","0","3"],["84120","0.82","0","13"],["84120.3","167.58","0","1"],["84120.7","0.01","0","1"],["84121.6","0.62","0","4"],["84121.8","0.02","0","2"],["84122","0.01","0","1"],["84122.7","89.37","0","3"],["84122.8","9.17","0","1"],["84124.5","11.92","0","2"],["84124.6","132.19","0","5"],["84126.7","56.67","0","3"],["84128.8","0.01","0","1"],["84131.1","15.43","0","4"],["84131.5","48.36","0","3"],["84133.1","9.14","0","1"],["84133.9","0.01","0","1"],["84135.2","6.22","0","1"],["84138.3","0.14","0","3"],["84139.5","0.03","0","2"],["84141.1","101.55","0","6"],["84144","23.67","0","10"],["84145","5","0","1"],["84147.8","0.01","0","1"],["84149.1","0.61","0","2"],["84150.6","40.73","0","2"],["84150.7","73.68","0","2"],["84152","55.43","0","2"],["84152.8","0.01","0","1"],["84153.3","0.19","0","11"],["84153.4","0","0","0"],["84153.5","0","0","0"],["84153.6","0","0","0"]],"bids":[["84099.5","1684.71","0","53"],["84098","5.01","0","1"],["84097.9","16.17","0","2"],["84097.5","0.01","0","1"],["84097.3","0.23","0","1"],["84097.1","0","0","0"],["84097","0.24","0","2"],["84096.7","0.01","0","1"],["84095.9","2.39","0","3"],["84095.8","30.56","0","4"],["84095.7","196.47","0","7"],["84095.6","15.51","0","4"],["84095.5","77.2","0","11"],["84095.1","0.01","0","1"],["84094.1","0.01","0","1"],["84093.4","424.72","0","43"],["84092.4","240.87","0","4"],["84091","258.95","0","5"],["84090.9","0","0","0"],["84090.6","11.91","0","2"],["84089.2","273.64","0","4"],["84089.1","70.92","0","3"],["84088.8","0.02","0","1"],["84088.5","135.73","0","2"],["84088.1","0.02","0","1"],["84084.9","0.94","0","2"],["84084.7","0.01","0","1"],["84084.2","0.02","0","2"],["84084","191.95","0","7"],["84083.9","0.02","0","1"],["84083.4","0","0","0"],["84083.3","0","0","0"],["84082.7","2.6","0","1"],["84082.3","1","0","1"],["84082.1","0","0","0"],["84081.3","2.48","0","3"],["84079.6","167.49","0","1"],["84079.5","0.03","0","2"],["84079","0.59","0","1"],["84077.2","0.05","0","2"],["84077.1","0","0","0"],["84076.4","2.37","0","1"],["84076","0","0","0"],["84075.5","50","0","1"],["84068.9","5.99","0","1"],["84068.7","324.01","0","3"],["84068.4","44.71","0","4"],["84068.2","17.13","0","4"],["84067.5","0.35","0","3"],["84067.3","0.01","0","1"],["84059.4","0.33","0","1"],["84056.7","0.63","0","3"],["84054.5","0","0","0"],["84051.3","1.55","0","5"],["84040.6","43.52","0","1"],["84039.8","0","0","0"],["84039.1","0.3","0","2"],["84038.3","0.6","0","1"],["84037.5","51.33","0","3"],["84037.4","0","0","0"],["84037.3","0","0","0"],["84037.1","0","0","0"],["84036.8","0","0","0"],["84036.7","0","0","0"],["84036.6","0","0","0"],["84036.2","0","0","0"],["84036","0","0","0"]],"ts":"1790439596700","checksum":0,"seqId":342177341801,"prevSeqId":342177341229}]}
91953284033407	{"arg":{"channel":"bbo-tbt","instId":"BTC-USDT-SWAP"},"data":[{"asks":[["84099.6","309.47","0","14"]],"bids":[["84099.5","1688.06","0","54"]],"ts":"1790439596710","seqId":342177341817}]}
91953291365310	{"arg":{"channel":"bbo-tbt","instId":"BTC-USDT-SWAP"},"data":[{"asks":[["84099.6","309.49","0","15"]],"bids":[["84099.5","1699.43","0","57"]],"ts":"1790439596720","seqId":342177341838}]}
91953298721114	{"arg":{"channel":"bbo-tbt","instId":"BTC-USDT-SWAP"},"data":[{"asks":[["84099.6","309.49","0","15"]],"bids":[["84099.5","1721.41","0","58"]],"ts":"1790439596730","seqId":342177341858}]}
91953307621184	{"arg":{"channel":"bbo-tbt","instId":"BTC-USDT-SWAP"},"data":[{"asks":[["84099.6","309.49","0","15"]],"bids":[["84099.5","1734.87","0","60"]],"ts":"1790439596740","seqId":342177341890}]}
91953316872699	{"arg":{"channel":"bbo-tbt","instId":"BTC-USDT-SWAP"},"data":[{"asks":[["84099.6","309.49","0","15"]],"bids":[["84099.5","1735.55","0","63"]],"ts":"1790439596750","seqId":342177341895}]}
91953326198603	{"arg":{"channel":"bbo-tbt","instId":"BTC-USDT-SWAP"},"data":[{"asks":[["84099.6","309.49","0","15"]],"bids":[["84099.5","1746.86","0","67"]],"ts":"1790439596760","seqId":342177341926}]}
91953335598432	{"arg":{"channel":"bbo-tbt","instId":"BTC-USDT-SWAP"},"data":[{"asks":[["84099.6","309.49","0","15"]],"bids":[["84099.5","1759.41","0","70"]],"ts":"1790439596770","seqId":342177341938}]}
91953362697838	{"arg":{"channel":"books","instId":"BTC-USDT-SWAP"},"action":"update","data":[{"asks":[["84099.6","309.49","0","15"],["84105","0.02","0","2"],["84108","1.2","0","3"],["84109.2","0.18","0","6"],["84112.2","3.42","0","2"],["84113.2","16.07","0","1"],["84113.4","229.09","0","5"],["84114","0.01","0","1"],["84114.9","0.01","0","1"],["84117.6","0.03","0","3"],["84121.8","0.03","0","3"],["84127.5","0.96","0","2"],["84128.3","0.35","0","4"],["84142.8","0.91","0","8"],["84153.3","0","0","0"]],"bids":[["84099.5","1759.41","0","70"],["84097.3","0","0","0"],["84097","0.01","0","1"],["84096.1","0.46","0","2"],["84095.9","0.02","0","2"],["84095.8","4.79","0","4"],["84095.6","10.75","0","3"],["84095.5","33.21","0","7"],["84095.2","0.07","0","2"],["84093.9","22.06","0","4"],["84093.7","2.39","0","3"],["84093.4","419.21","0","42"],["84093.3","0.06","0","1"],["84091.4","8.25","0","2"],["84089.6","0.01","0","1"],["84085.9","0.73","0","2"],["84084.9","1.89","0","3"],["84073","0.02","0","2"],["84068","0","0","0"],["84065.9","0.01","0","1"],["84064.8","0.01","0","1"],["84060.8","663.48","0","4"],["84042.1","0","0","0"],["84041.3","0","0","0"],["84037.3","0.02","0","2"]],"ts":"1790439596800","checksum":0,"seqId":342177342002,"prevSeqId":342177341801}]}
91953399132629	{"arg":{"channel":"bbo-tbt","instId":"BTC-USDT-SWAP"},"data":[{"asks":[["84099.6","325.38","0","16"]],"bids":[["84099.5","1783.36","0","71"]],"ts":"1790439596840","seqId":342177342055}]}
91953428044007	{"arg":{"channel":"bbo-tbt","instId":"BTC-USDT-SWAP"},"data":[{"asks":[["84099.6","325.47","0","17"]],"bids":[["84099.5","1783.36","0","71"]],"ts":"1790439596870","seqId":342177342067}]}
91953453695886	{"arg":{"channel":"books","instId":"BTC-USDT-SWAP"},"action":"update","data":[{"asks":[["84099.6","325.47","0","17"],["84100","1124.44","0","11"],["84102","1.93","0","3"],["84110","2293.07","0","125"],["84110.4","1.04","0","2"],["84111.4","0.01","0","1"],["84113.5","0.23","0","1"],["84113.8","226.83","0","4"],["84114.6","0.04","0","4"],["84118","403.21","0","5"],["84118.5","0.97","0","3"],["84122.7","119.08","0","4"],["84123.2","0.01","0","1"],["84124.6","98.75","0","4"],["84126.7","56.6","0","2"],["84131.1","12.38","0","3"],["84150.1","0.51","0","2"],["84153","0","0","0"]],"bids":[["84099.5","1783.36","0","71"],["84097","0.8","0","2"],["84093.6","71.55","0","3"],["84093.4","393.02","0","41"],["84092.6","64.55","0","5"],["84088.9","108.63","0","2"],["84083.8","75.39","0","3"],["84079.9","45.77","0","2"],["84074.3","11.91","0","3"],["84056.9","110.44","0","5"]],"ts":"1790439596900","checksum":0,"seqId":342177342083,"prevSeqId":342177342002}]}
91953535217127	{"arg":{"channel":"bbo-tbt","instId":"BTC-USDT-SWAP"},"data":[{"asks":[["84099.6","325.47","0","17"]],"bids":[["84099.5","1784.55","0","72"]],"ts":"1790439596990","seqId":342177342289}]}
91953544574628	{"arg":{"channel":"bbo-tbt","instId":"BTC-USDT-SWAP"},"data":[{"asks":[["84099.6","325.47","0","17"]],"bids":[["84099.5","1783.36","0","71"]],"ts":"1790439597000","seqId":342177342301}]}
91953544574628	{"arg":{"channel":"books","instId":"BTC-USDT-SWAP"},"action":"update","data":[{"asks":[["84100.8","0.02","0","2"],["84111.1","0.14","0","3"],["84111.4","0","0","0"],["84113.4","228.99","0","4"],["84117.9","1.22","0","4"],["84122","187.55","0","2"],["84122.6","0","0","0"],["84126.4","0.95","0","1"],["84127.5","0.01","0","1"],["84142.8","0.9","0","7"],["84153","0.12","0","3"]],"bids":[["84096.5","4.77","0","2"],["84096.1","238.25","0","3"],["84095.9","2.39","0","3"],["84095.8","0.03","0","3"],["84093.7","0.02","0","2"],["84093.4","392.88","0","38"],["84093.3","0","0","0"],["84093.2","0","0","0"],["84093.1","0","0","0"],["84093","0.02","0","2"],["84092.4","374.89","0","5"],["84090.9","0.02","0","1"],["84089.1","70.9","0","2"],["84088.8","0.04","0","2"],["84088.1","0","0","0"],["84084.9","0.94","0","2"],["84084.1","221.55","0","3"],["84084","191.97","0","8"],["84083.9","0","0","0"],["84081.2","0","0","0"],["84080.5","86.06","0","2"],["84079.5","0.01","0","1"],["84078.6","1.44","0","2"],["84073.5","27.46","0","3"],["84037.1","0.01","0","1"],["84036.8","8.24","0","1"],["84036.7","18.28","0","1"],["84036.6","0.59","0","1"],["84036.2","0.95","0","1"]],"ts":"1790439597000","checksum":0,"seqId":342177342301,"prevSeqId":342177342083}]}
91953553077873	{"arg":{"channel":"bbo-tbt","instId":"BTC-USDT-SWAP"},"data":[{"asks":[["84099.6","393.3","0","22"]],"bids":[["84099.5","1797.18","0","73"]],"ts":"1790439597010","seqId":342177342364}]}
91953561957103	{"arg":{"channel":"bbo-tbt","instId":"BTC-USDT-SWAP"},"data":[{"asks":[["84099.6","393.3","0","22"]],"bids":[["84099.5","1798.37","0","74"]],"ts":"1790439597020","seqId":342177342381}]}
91953571749857	{"arg":{"channel":"bbo-tbt","instId":"BTC-USDT-SWAP"},"data":[{"asks":[["84099.6","393.3","0","22"]],"bids":[["84099.5","1797.18","0","73"]],"ts":"1790439597030","seqId":342177342394}]}
91953589853927	{"arg":{"channel":"bbo-tbt","instId":"BTC-USDT-SWAP"},"data":[{"asks":[["84099.6","393.3","0","22"]],"bids":[["84099.5","1809.78","0","76"]],"ts":"1790439597050","seqId":342177342455}]}
91953620046503	{"arg":{"channel":"bbo-tbt","instId":"BTC-USDT-SWAP"},"data":[{"asks":[["84099.6","393.3","0","22"]],"bids":[["84099.5","1810.97","0","77"]],"ts":"1790439597080","seqId":342177342495}]}
91953628115108	{"arg":{"channel":"bbo-tbt","instId":"BTC-USDT-SWAP"},"data":[{"asks":[["84099.6","393.3","0","22"]],"bids":[["84099.5","1809.78","0","76"]],"ts":"1790439597090","seqId":342177342522}]}
91953636825668	{"arg":{"channel":"bbo-tbt","instId":"BTC-USDT-SWAP"},"data":[{"asks":[["84099.6","393.3","0","22"]],"bids":[["84099.5","1810.97","0","77"]],"ts":"1790439597100","seqId":342177342541}]}
91953636825668	{"arg":{"channel":"books","instId":"BTC-USDT-SWAP"},"action":"update","data":[{"asks":[["84099.6","393.3","0","22"],["84099.9","2.39","0","3"],["84100","1063.3","0","9"],["84100.4","0.01","0","1"],["84101.2","12.12","0","1"],["84103.2","0.02","0","2"],["84103.8","0.03","0","3"],["84104","0.02","0","2"],["84104.6","0.01","0","1"],["84105.8","0.01","0","1"],["84108.4","0.92","0","3"],["84109.6","0.1","0","1"],["84118","404.03","0","5"],["84118.5","0.22","0","1"],["84121.7","285.47","0","4"],["84121.8","172.73","0","5"],["84122","0.01","0","1"],["84124.6","97.93","0","3"],["84126","1.07","0","6"],["84126.3","238.95","0","18"],["84126.4","0","0","0"],["84135.8","238.38","0","1"],["84152.7","77.28","0","3"],["84153","0","0","0"]],"bids":[["84099.5","1810.97","0","77"],["84097","8.39","0","3"],["84096.2","2.37","0","1"],["84096.1","237.79","0","1"],["84095.9","0","0","0"],["84095.7","196.93","0","9"],["84094.1","0","0","0"],["84093.6","71.91","0","2"],["84093.4","367.13","0","34"],["84091.3","238.39","0","2"],["84084.1","220.6","0","2"],["84083.8","74.28","0","2"],["84083.2","0.98","0","4"],["84079.9","284.15","0","3"],["84065.7","221.72","0","4"],["84036","8.45","0","1"]],"ts":"1790439597100","checksum":0,"seqId":342177342541,"prevSeqId":342177342301}]}
91953644844273	{"arg":{"channel":"bbo-tbt","instId":"BTC-USDT-SWAP"},"data":[{"asks":[["84099.6","393.3","0","22"]],"bids":[["84099.5","1809.78","0","76"]],"ts":"1790439597110","seqId":342177342549}]}
91953653920425	{"arg":{"channel":"bbo-tbt","instId":"BTC-USDT-SWAP"},"data":[{"asks":[["84099.6","393.3","0","22"]],"bids":[["84099.5","1811.67","0","78"]],"ts":"1790439597120","seqId":342177342573}]}
91953673470066	{"arg":{"channel":"bbo-tbt","instId":"BTC-USDT-SWAP"},"data":[{"asks":[["84099.6","393.3","0","22"]],"bids":[["84099.5","1812.86","0","79"]],"ts":"1790439597140","seqId":342177342591}]}
91953680901478	{"arg":{"channel":"bbo-tbt","instId":"BTC-USDT-SWAP"},"data":[{"asks":[["84099.6","393.3","0","22"]],"bids":[["84099.5","1811.67","0","78"]],"ts":"1790439597150","seqId":342177342612}]}
91953726327170	{"arg":{"channel":"bbo-tbt","instId":"BTC-USDT-SWAP"},"data":[{"asks":[["84099.6","393.41","0","22"]],"bids":[["84099.5","1811.67","0","78"]],"ts":"1790439597200","seqId":342177342746}]}
91953726327170	{"arg":{"channel":"books","instId":"BTC-USDT-SWAP"},"action":"update","data":[{"asks":[["84099.6","393.41","0","22"],["84099.8","0.02","0","2"],["84100.4","0","0","0"],["84102.5","0","0","0"],["84102.7","0","0","0"],["84104.2","0.1","0","1"],["84104.6","0","0","0"],["84105.4","0","0","0"],["84106.2","0.02","0","2"],["84106.8","0.01","0","1"],["84107.9","0","0","0"],["84108","1.22","0","5"],["84109.2","0.17","0","5"],["84110.3","0.01","0","1"],["84112.5","0.04","0","3"],["84112.7","0","0","0"],["84113.1","1.65","0","2"],["84113.9","0","0","0"],["84114.5","68.01","0","2"],["84116.4","1.2","0","2"],["84116.6","0.01","0","1"],["84117","0.6","0","2"],["84117.4","0","0","0"],["84117.9","0.03","0","3"],["84118.4","0.01","0","1"],["84118.6","0.04","0","2"],["84118.7","14.53","0","3"],["84119.1","0.07","0","2"],["84119.8","141.75","0","5"],["84120.2","0.01","0","1"],["84120.7","237.81","0","3"],["84121.2","0.59","0","2"],["84121.3","59.6","0","3"],["84121.6","0.63","0","5"],["84121.7","47.69","0","4"],["84121.8","116.34","0","4"],["84122.6","0.01","0","1"],["84125.6","14.04","0","5"],["84126","1.08","0","7"],["84126.3","0.57","0","17"],["84126.5","277.19","0","6"],["84128.7","0.01","0","1"],["84129.6","0.01","0","1"],["84131.4","0.05","0","5"],["84135.8","0","0","0"],["84136","265.06","0","6"],["84140.1","0.61","0","2"],["84141","2.87","0","3"],["84141.1","101.54","0","5"],["84142.5","0.01","0","1"],["84143.2","12.83","0","3"],["84148.8","0.01","0","1"],["84149.3","35.79","0","3"],["84149.4","206.67","0","2"],["84149.9","0.02","0","2"],["84150.6","40.74","0","3"],["84152.6","2.59","0","4"],["84153","0.12","0","3"],["84153.3","0.19","0","11"],["84153.4","0.01","0","1"],["84153.5","0.02","0","1"]],"bids":[["84099.5","1811.67","0","78"],["84098","7.09","0","2"],["84096.9","1.29","0","2"],["84079.9","45.77","0","2"],["84079.7","238.39","0","2"]],"ts":"1790439597200","checksum":0,"seqId":342177342746,"prevSeqId":342177342541}]}
91953737048483	{"arg":{"channel":"bbo-tbt","instId":"BTC-USDT-SWAP"},"data":[{"asks":[["84099.6","393.41","0","22"]],"bids":[["84099.5","1811.67","0","77"]],"ts":"1790439597210","seqId":342177342777}]}
91953748039452	{"arg":{"channel":"bbo-tbt","instId":"BTC-USDT-SWAP"},"data":[{"asks":[["84099.6","393.41","0","22"]],"bids":[["84099.5","1811.71","0","78"]],"ts":"1790439597220","seqId":342177342793}]}
91953819210289	{"arg":{"channel":"books","instId":"BTC-USDT-SWAP"},"action":"update","data":[{"asks":[["84099.9","0.02","0","2"],["84102","1.71","0","2"],["84106.2","0.03","0","3"],["84107.9","0.01","0","1"],["84108.1","12.79","0","3"],["84109.6","2.47","0","2"],["84112.2","0.24","0","1"],["84118","404.04","0","5"],["84120.4","237.8","0","2"],["84120.7","0.02","0","2"],["84124.6","97.92","0","2"],["84153.5","0","0","0"]],"bids":[["84099.5","1811.71","0","78"],["84097.1","0.77","0","3"],["84097","7.61","0","3"],["84096.6","0.03","0","3"],["84095.7","196.47","0","7"],["84095.6","11.21","0","5"],["84093.6","72.45","0","2"],["84091","259.17","0","6"],["84084.9","0.72","0","1"],["84083.8","73.74","0","2"],["84036","0","0","0"]],"ts":"1790439597300","checksum":0,"seqId":342177342909,"prevSeqId":342177342746}]}
