{"stream":"btcusdt@depth@100ms","data":{"e":"depthUpdate","E":1789469121904,"T":1789469121836,"s":"BTCUSDT","ps":"BTCUSDT","U":429012275424,"u":429012275789,"pu":429012275360,"b":[],"a":[["77021.60","650.0043"]],"st":1}}
{"stream":"btcusdt@depth@100ms","data":{"e":"depthUpdate","E":1789469122060,"T":1789469122045,"s":"BTCUSDT","ps":"BTCUSDT","U":429012276615,"u":429012277528,"pu":429012275789,"b":[],"a":[["76968.30","1191.3336"]],"st":1}}
{"stream":"btcusdt@depth@100ms","data":{"e":"depthUpdate","E":1789469122186,"T":1789469122181,"s":"BTCUSDT","ps":"BTCUSDT","U":429012277602,"u":429012278639,"pu":429012277528,"b":[],"a":[["76968.30","994.0235"],["77021.70","30.5523"],["77022.10","15.2713"],["77022.70","15.2713"],["77024.80","405.2748"],["77025.00","15.2713"],["77025.20","15.2713"],["77026.60","30.5426"],["77027.30","15.2713"],["77029.20","15.2713"],["77029.60","15.2713"],["77030.40","15.2713"]],"st":1}}
{"stream":"btcusdt@depth@100ms","data":{"e":"depthUpdate","E":1789469122290,"T":1789469122260,"s":"BTCUSDT","ps":"BTCUSDT","U":429012278684,"u":429012279216,"pu":429012278639,"b":[["76947.30","0.0361"]],"a":[["77021.90","15.2713"],["77024.00","15.2713"],["77025.30","15.2713"],["77026.50","15.2713"],["77026.70","15.2720"],["77029.20","30.5426"],["77029.60","30.5426"]],"st":1}}
{"stream":"btcusdt@depth@100ms","data":{"e":"depthUpdate","E":1789469122410,"T":1789469122388,"s":"BTCUSDT","ps":"BTCUSDT","U":429012279430,"u":429012280126,"pu":429012279216,"b":[["76885.80","0.0000"]],"a":[["84000.00","519.0698"]],"st":1}}
{"stream":"btcusdt@depth@100ms","data":{"e":"depthUpdate","E":1789469122808,"T":1789469122695,"s":"BTCUSDT","ps":"BTCUSDT","U":429012282643,"u":429012282643,"pu":429012280126,"b":[["76804.90","0.0000"]],"a":[],"st":1}}
{"stream":"btcusdt@depth@100ms","data":{"e":"depthUpdate","E":1789469123020,"T":1789469122959,"s":"BTCUSDT","ps":"BTCUSDT","U":429012285135,"u":429012285724,"pu":429012282643,"b":[["73099.90","0.0020"],["76949.90","0.0129"]],"a":[],"st":1}}
{"stream":"btcusdt@depth@100ms","data":{"e":"depthUpdate","E":1789469123154,"T":1789469123044,"s":"BTCUSDT","ps":"BTCUSDT","U":429012286781,"u":429012286794,"pu":429012285724,"b":[["76704.80","0.0000"],["76708.90","0.0010"],["76712.20","0.0000"],["76715.30","0.0010"],["76719.50","0.0000"],["76721.70","0.0010"]],"a":[["77194.00","0.0000"],["77194.60","0.0010"],["77201.10","0.0010"],["77201.30","0.0000"],["77207.50","0.0010"],["77208.70","0.0000"],["77213.90","0.0020"],["77216.00","0.0000"]],"st":1}}
{"stream":"btcusdt@depth@100ms","data":{"e":"depthUpdate","E":1789469123736,"T":1789469123651,"s":"BTCUSDT","ps":"BTCUSDT","U":429012292786,"u":429012292906,"pu":429012286794,"b":[],"a":[["76968.30","994.0223"],["77021.60","650.0055"]],"st":1}}
{"stream":"btcusdt@depth@100ms","data":{"e":"depthUpdate","E":1789469123922,"T":1789469123865,"s":"BTCUSDT","ps":"BTCUSDT","U":429012294149,"u":429012294496,"pu":429012292906,"b":[],"a":[["76968.30","994.0198"],["77021.60","650.0065"]],"st":1}}
{"stream":"btcusdt@depth@100ms","data":{"e":"depthUpdate","E":1789469124074,"T":1789469124049,"s":"BTCUSDT","ps":"BTCUSDT","U":429012295402,"u":429012296081,"pu":429012294496,"b":[],"a":[["76968.30","994.0191"],["77021.60","650.0087"]],"st":1}}
{"stream":"btcusdt@depth@100ms","data":{"e":"depthUpdate","E":1789469124308,"T":1789469124191,"s":"BTCUSDT","ps":"BTCUSDT","U":429012297423,"u":429012297423,"pu":429012296081,"b":[["73100.00","0.0107"]],"a":[],"st":1}}
{"stream":"btcusdt@depth@100ms","data":{"e":"depthUpdate","E":1789469124874,"T":1789469124771,"s":"BTCUSDT","ps":"BTCUSDT","U":429012302352,"u":429012302352,"pu":429012297423,"b":[],"a":[["77699.00","0.0025"],["77699.30","0.0000"]],"st":1}}
{"stream":"btcusdt@depth@100ms","data":{"e":"depthUpdate","E":1789469125036,"T":1789469124935,"s":"BTCUSDT","ps":"BTCUSDT","U":429012304330,"u":429012304330,"pu":429012302352,"b":[["38483.00","0.0016"]],"a":[],"st":1}}
{"stream":"btcusdt@depth@100ms","data":{"e":"depthUpdate","E":1789469125260,"T":1789469125159,"s":"BTCUSDT","ps":"BTCUSDT","U":429012307244,"u":429012307244,"pu":429012304330,"b":[],"a":[["76987.00","0.0000"]],"st":1}}
{"stream":"btcusdt@depth@100ms","data":{"e":"depthUpdate","E":1789469125406,"T":1789469125291,"s":"BTCUSDT","ps":"BTCUSDT","U":429012308688,"u":429012308688,"pu":429012307244,"b":[],"a":[["77699.20","0.0000"]],"st":1}}
{"stream":"btcusdt@depth@100ms","data":{"e":"depthUpdate","E":1789469125520,"T":1789469125467,"s":"BTCUSDT","ps":"BTCUSDT","U":429012309992,"u":429012310482,"pu":429012308688,"b":[],"a":[["76968.30","337.1577"]],"st":1}}
{"stream":"btcusdt@depth@100ms","data":{"e":"depthUpdate","E":1789469125648,"T":1789469125642,"s":"BTCUSDT","ps":"BTCUSDT","U":429012311362,"u":429012312227,"pu":429012310482,"b":[["38483.10","0.0000"],["76769.00","0.0000"]],"a":[["77021.70","225.5523"],["77699.00","0.0050"]],"st":1}}
{"stream":"btcusdt@depth@100ms","data":{"e":"depthUpdate","E":1789469125750,"T":1789469125703,"s":"BTCUSDT","ps":"BTCUSDT","U":429012312271,"u":429012312738,"pu":429012312227,"b":[],"a":[["76983.30","0.0000"],["77021.70","680.5523"]],"st":1}}
{"stream":"btcusdt@depth@100ms","data":{"e":"depthUpdate","E":1789469125916,"T":1789469125913,"s":"BTCUSDT","ps":"BTCUSDT","U":429012313678,"u":429012314671,"pu":429012312738,"b":[["77012.00","66.0255"],["77014.70","66.1440"],["77015.20","61.9700"],["77019.50","65.9609"]],"a":[["76968.30","0.0000"],["76969.90","0.0000"],["76970.00","0.0000"],["76975.20","0.0000"],["76975.30","0.0000"],["76980.00","0.0000"],["76980.10","0.0000"],["76990.10","0.0000"],["77009.80","0.0000"],["77010.00","0.0000"],["77012.60","0.0000"],["77013.90","0.0000"],["77015.90","0.0000"],["77017.80","0.0000"],["77017.90","0.0000"],["77019.50","0.0000"],["77021.20","524.8422"]],"st":1}}
{"stream":"btcusdt@depth@100ms","data":{"e":"depthUpdate","E":1789469126020,"T":1789469125975,"s":"BTCUSDT","ps":"BTCUSDT","U":429012314717,"u":429012315169,"pu":429012314671,"b":[["76708.90","0.0000"],["76715.30","0.0000"],["76721.70","0.0000"],["76787.50","0.0010"],["76788.00","0.0010"],["76788.60","0.0010"],["76908.70","0.0051"],["77019.20","65.6253"]],"a":[["77194.60","0.0000"],["77201.10","0.0000"],["77207.50","0.0000"],["77213.90","0.0000"],["77251.90","54.4666"],["77252.50","42.0673"],["77253.10","0.0010"],["77253.70","19.9149"]],"st":1}}
{"stream":"btcusdt@depth@100ms","data":{"e":"depthUpdate","E":1789469126232,"T":1789469126165,"s":"BTCUSDT","ps":"BTCUSDT","U":429012316786,"u":429012317134,"pu":429012315169,"b":[["76308.20","0.0036"],["76403.30","0.0750"],["76666.60","1.2391"],["76734.50","0.0050"],["76806.70","0.0000"],["76888.50","0.0050"]],"a":[["77021.20","524.8413"],["77021.70","680.5532"],["77091.90","0.0000"],["77111.30","0.0000"],["77152.20","0.0050"],["77200.90","0.0000"],["77306.20","0.0050"]],"st":1}}
{"stream":"btcusdt@depth@100ms","data":{"e":"depthUpdate","E":1789469126426,"T":1789469126398,"s":"BTCUSDT","ps":"BTCUSDT","U":429012318160,"u":429012319241,"pu":429012317134,"b":[["76834.30","0.0000"]],"a":[["77021.20","524.8387"],["77092.50","0.0043"]],"st":1}}
{"stream":"btcusdt@depth@100ms","data":{"e":"depthUpdate","E":1789469126562,"T":1789469126517,"s":"BTCUSDT","ps":"BTCUSDT","U":429012319731,"u":429012320406,"pu":429012319241,"b":[],"a":[["77021.20","524.8380"],["77021.60","650.0103"]],"st":1}}
{"stream":"btcusdt@depth@100ms","data":{"e":"depthUpdate","E":1789469126702,"T":1789469126673,"s":"BTCUSDT","ps":"BTCUSDT","U":429012321202,"u":429012321799,"pu":429012320406,"b":[["77019.50","65.9529"]],"a":[["77021.60","650.0120"]],"st":1}}
{"stream":"btcusdt@depth@100ms","data":{"e":"depthUpdate","E":1789469126892,"T":1789469126790,"s":"BTCUSDT","ps":"BTCUSDT","U":429012322700,"u":429012322700,"pu":429012321799,"b":[],"a":[["77117.80","0.0000"]],"st":1}}
{"stream":"btcusdt@depth@100ms","data":{"e":"depthUpdate","E":1789469127014,"T":1789469126906,"s":"BTCUSDT","ps":"BTCUSDT","U":429012323966,"u":429012323966,"pu":429012322700,"b":[["77019.50","65.9449"]],"a":[],"st":1}}
{"stream":"btcusdt@depth@100ms","data":{"e":"depthUpdate","E":1789469127116,"T":1789469127051,"s":"BTCUSDT","ps":"BTCUSDT","U":429012324739,"u":429012325084,"pu":429012323966,"b":[["77019.50","65.2837"]],"a":[["77021.20","524.6835"]],"st":1}}
{"stream":"btcusdt@depth@100ms","data":{"e":"depthUpdate","E":1789469127308,"T":1789469127296,"s":"BTCUSDT","ps":"BTCUSDT","U":429012326246,"u":429012326879,"pu":429012325084,"b":[["76899.70","0.0000"]],"a":[["77021.20","524.6186"]],"st":1}}
{"stream":"btcusdt@depth@100ms","data":{"e":"depthUpdate","E":1789469127790,"T":1789469127674,"s":"BTCUSDT","ps":"BTCUSDT","U":429012329755,"u":429012329755,"pu":429012326879,"b":[],"a":[["77052.40","41.3852"]],"st":1}}
{"stream":"btcusdt@depth@100ms","data":{"e":"depthUpdate","E":1789469128216,"T":1789469128151,"s":"BTCUSDT","ps":"BTCUSDT","U":429012334091,"u":429012334436,"pu":429012329755,"b":[["76918.50","0.0012"],["77019.50","64.9880"]],"a":[["85939.50","0.0000"]],"st":1}}
{"stream":"btcusdt@depth@100ms","data":{"e":"depthUpdate","E":1789469128340,"T":1789469128238,"s":"BTCUSDT","ps":"BTCUSDT","U":429012335259,"u":429012335259,"pu":429012334436,"b":[],"a":[["77021.20","524.6161"]],"st":1}}
{"stream":"btcusdt@depth@100ms","data":{"e":"depthUpdate","E":1789469128502,"T":1789469128478,"s":"BTCUSDT","ps":"BTCUSDT","U":429012336914,"u":429012337628,"pu":429012335259,"b":[["76853.10","261.6380"],["77019.50","64.9870"]],"a":[["77021.20","524.6151"],["81193.30","0.0000"]],"st":1}}
{"stream":"btcusdt@depth@100ms","data":{"e":"depthUpdate","E":1789469128642,"T":1789469128540,"s":"BTCUSDT","ps":"BTCUSDT","U":429012338126,"u":429012338218,"pu":429012337628,"b":[],"a":[["77021.20","524.6141"],["77021.60","650.0130"]],"st":1}}
{"stream":"btcusdt@depth@100ms","data":{"e":"depthUpdate","E":1789469128782,"T":1789469128741,"s":"BTCUSDT","ps":"BTCUSDT","U":429012339514,"u":429012340183,"pu":429012338218,"b":[["66954.80","0.0000"]],"a":[["77021.20","524.6132"],["77021.60","650.0140"],["77772.70","0.0268"]],"st":1}}
{"stream":"btcusdt@depth@100ms","data":{"e":"depthUpdate","E":1789469128934,"T":1789469128923,"s":"BTCUSDT","ps":"BTCUSDT","U":429012341029,"u":429012341915,"pu":429012340183,"b":[["76787.70","0.0012"]],"a":[["77021.60","650.0149"],["78618.90","0.0265"]],"st":1}}
{"stream":"btcusdt@depth@100ms","data":{"e":"depthUpdate","E":1789469129074,"T":1789469129006,"s":"BTCUSDT","ps":"BTCUSDT","U":429012342292,"u":429012342691,"pu":429012341915,"b":[["71701.00","0.0000"],["76908.70","0.0000"]],"a":[],"st":1}}
{"stream":"btcusdt@depth@100ms","data":{"e":"depthUpdate","E":1789469129228,"T":1789469129126,"s":"BTCUSDT","ps":"BTCUSDT","U":429012343877,"u":429012343877,"pu":429012342691,"b":[],"a":[["79542.00","0.0324"]],"st":1}}
{"stream":"btcusdt@depth@100ms","data":{"e":"depthUpdate","E":1789469129360,"T":1789469129324,"s":"BTCUSDT","ps":"BTCUSDT","U":429012345077,"u":429012345415,"pu":429012343877,"b":[["76959.60","0.0007"]],"a":[["77047.00","0.0051"],["80542.10","0.0258"]],"st":1}}
{"stream":"btcusdt@depth@100ms","data":{"e":"depthUpdate","E":1789469129626,"T":1789469129524,"s":"BTCUSDT","ps":"BTCUSDT","U":429012347154,"u":429012347154,"pu":429012345415,"b":[],"a":[["81619.00","0.0255"]],"st":1}}
{"stream":"btcusdt@depth@100ms","data":{"e":"depthUpdate","E":1789469129842,"T":1789469129827,"s":"BTCUSDT","ps":"BTCUSDT","U":429012348807,"u":429012349759,"pu":429012347154,"b":[["73099.90","0.0000"],["73100.00","0.0127"]],"a":[["77021.20","524.6117"],["77021.70","680.5547"],["77698.80","0.0025"],["77699.00","0.0025"],["82772.90","0.0251"]],"st":1}}
{"stream":"btcusdt@depth@100ms","data":{"e":"depthUpdate","E":1789469129996,"T":1789469129929,"s":"BTCUSDT","ps":"BTCUSDT","U":429012350264,"u":429012351086,"pu":429012349759,"b":[["71712.50","0.0112"]],"a":[["77021.20","524.6057"],["84003.80","0.0248"]],"st":1}}
{"stream":"btcusdt@depth@100ms","data":{"e":"depthUpdate","E":1789469130148,"T":1789469130087,"s":"BTCUSDT","ps":"BTCUSDT","U":429012352678,"u":429012353315,"pu":429012351086,"b":[["76906.40","0.0000"],["77019.60","0.0238"]],"a":[["77021.20","524.6050"],["77021.70","680.5554"],["77071.30","0.0012"]],"st":1}}
{"stream":"btcusdt@depth@100ms","data":{"e":"depthUpdate","E":1789469130260,"T":1789469130161,"s":"BTCUSDT","ps":"BTCUSDT","U":429012354157,"u":429012354182,"pu":429012353315,"b":[["66972.90","0.0040"],["76787.50","0.0000"],["76787.60","0.0010"],["76788.00","0.0000"],["76788.20","0.0010"],["76788.60","0.0000"],["76788.70","0.0010"]],"a":[["77253.00","19.9139"],["77253.10","0.0000"],["77253.60","12.3964"],["77253.70","19.9129"]],"st":1}}
{"stream":"btcusdt@depth@100ms","data":{"e":"depthUpdate","E":1789469130438,"T":1789469130336,"s":"BTCUSDT","ps":"BTCUSDT","U":429012356038,"u":429012356038,"pu":429012354182,"b":[],"a":[["77699.00","0.0000"]],"st":1}}
{"stream":"btcusdt@depth@100ms","data":{"e":"depthUpdate","E":1789469130562,"T":1789469130553,"s":"BTCUSDT","ps":"BTCUSDT","U":429012357506,"u":429012358792,"pu":429012356038,"b":[["77019.60","0.0206"]],"a":[["77021.10","0.0032"],["77021.60","650.0161"],["77136.70","0.0012"],["81191.50","0.0099"]],"st":1}}
{"stream":"btcusdt@depth@100ms","data":{"e":"depthUpdate","E":1789469130674,"T":1789469130592,"s":"BTCUSDT","ps":"BTCUSDT","U":429012359048,"u":429012359295,"pu":429012358792,"b":[],"a":[["77252.40","0.0010"],["77252.50","42.0663"],["77253.50","0.0020"],["77253.60","12.3944"],["77698.70","0.0025"]],"st":1}}
{"stream":"btcusdt@depth@100ms","data":{"e":"depthUpdate","E":1789469130782,"T":1789469130775,"s":"BTCUSDT","ps":"BTCUSDT","U":429012360251,"u":429012362129,"pu":429012359295,"b":[["73168.60","0.0020"],["77004.90","33.0921"],["77008.60","32.7830"],["77011.40","32.6980"],["77012.30","32.7268"],["77014.40","32.8717"],["77015.10","32.7526"],["77015.40","33.0281"],["77016.70","32.8842"],["77017.10","32.8434"],["77019.40","32.4492"],["77019.50","64.9764"],["77019.60","0.0000"]],"a":[["77021.10","0.0238"],["77021.60","650.0173"]],"st":1}}
{"stream":"btcusdt@depth@100ms","data":{"e":"depthUpdate","E":1789469130896,"T":1789469130891,"s":"BTCUSDT","ps":"BTCUSDT","U":429012362454,"u":429012364054,"pu":429012362129,"b":[["76787.50","0.0010"],["76787.60","0.0000"],["76788.10","0.0010"],["76788.20","0.0000"],["76788.60","0.0010"],["76788.70","0.0000"],["76904.80","0.0000"],["77008.20","48.8588"],["77013.30","49.3999"],["77018.30","49.2807"],["77019.60","48.6789"],["77019.70","0.0007"],["77020.80","48.9349"]],"a":[["77021.10","0.0231"],["77021.60","650.0180"],["77251.80","42.0673"],["77251.90","54.4656"],["77252.90","0.0010"],["77253.00","19.9129"],["85931.00","0.0031"]],"st":1}}
{"stream":"btcusdt@depth@100ms","data":{"e":"depthUpdate","E":1789469130998,"T":1789469130995,"s":"BTCUSDT","ps":"BTCUSDT","U":429012364136,"u":429012365532,"pu":429012364054,"b":[["76787.50","0.0000"],["76788.10","0.0000"],["76788.60","0.0000"],["76789.50","0.0010"],["76789.60","0.0010"],["76789.70","0.0010"],["77012.60","48.8034"],["77012.70","49.1902"],["77013.90","49.5257"],["77014.00","49.1431"],["77015.40","82.1362"],["77015.90","49.2454"],["77016.80","49.5369"],["77017.00","48.7491"],["77017.20","48.9184"],["77017.90","49.5715"],["77019.00","49.4698"],["77019.70","0.0000"],["77020.40","49.6196"],["77020.90","49.0521"],["77021.00","0.0007"]],"a":[["77251.80","42.0663"],["77252.10","0.0010"],["77252.20","0.0010"],["77252.30","0.0010"],["77252.40","0.0020"],["77252.90","0.0000"],["77253.50","0.0000"]],"st":1}}
{"stream":"btcusdt@depth@100ms","data":{"e":"depthUpdate","E":1789469131130,"T":1789469131054,"s":"BTCUSDT","ps":"BTCUSDT","U":429012365674,"u":429012366182,"pu":429012365532,"b":[["76789.50","0.0000"],["76789.60","0.0010"],["76789.70","0.0010"],["76789.80","0.0010"],["77014.90","48.8442"],["77016.30","49.4354"],["77020.30","0.0007"]],"a":[["77252.10","0.0000"],["77252.20","0.0010"],["77252.30","0.0010"],["77252.40","0.0010"],["77252.50","42.0683"]],"st":1}}
{"stream":"btcusdt@depth@100ms","data":{"e":"depthUpdate","E":1789469131582,"T":1789469131480,"s":"BTCUSDT","ps":"BTCUSDT","U":429012369520,"u":429012369520,"pu":429012366182,"b":[["76959.60","0.0000"]],"a":[],"st":1}}
{"stream":"btcusdt@depth@100ms","data":{"e":"depthUpdate","E":1789469131772,"T":1789469131670,"s":"BTCUSDT","ps":"BTCUSDT","U":429012370988,"u":429012370988,"pu":429012369520,"b":[["77019.50","64.9774"]],"a":[],"st":1}}
{"stream":"btcusdt@depth@100ms","data":{"e":"depthUpdate","E":1789469132152,"T":1789469132027,"s":"BTCUSDT","ps":"BTCUSDT","U":429012373732,"u":429012373732,"pu":429012370988,"b":[],"a":[["77021.10","0.0221"]],"st":1}}
{"stream":"btcusdt@depth@100ms","data":{"e":"depthUpdate","E":1789469132482,"T":1789469132458,"s":"BTCUSDT","ps":"BTCUSDT","U":429012376584,"u":429012377317,"pu":429012373732,"b":[],"a":[["77021.10","0.0205"],["77021.60","650.0196"],["77040.40","0.0007"]],"st":1}}
{"stream":"btcusdt@depth@100ms","data":{"e":"depthUpdate","E":1789469132692,"T":1789469132605,"s":"BTCUSDT","ps":"BTCUSDT","U":429012378734,"u":429012378917,"pu":429012377317,"b":[],"a":[["77021.10","0.0189"],["77021.60","650.0212"]],"st":1}}
{"stream":"btcusdt@depth@100ms","data":{"e":"depthUpdate","E":1789469133038,"T":1789469132936,"s":"BTCUSDT","ps":"BTCUSDT","U":429012381854,"u":429012381854,"pu":429012378917,"b":[],"a":[["77021.10","0.0181"]],"st":1}}
{"stream":"btcusdt@depth@100ms","data":{"e":"depthUpdate","E":1789469133338,"T":1789469133282,"s":"BTCUSDT","ps":"BTCUSDT","U":429012384359,"u":429012384776,"pu":429012381854,"b":[["76787.70","0.0000"],["76853.10","261.6368"],["76918.50","0.0000"]],"a":[["77021.60","650.0220"],["77071.30","0.0000"],["77112.70","0.0010"],["77136.70","0.0000"]],"st":1}}
{"stream":"btcusdt@depth@100ms","data":{"e":"depthUpdate","E":1789469134302,"T":1789469134200,"s":"BTCUSDT","ps":"BTCUSDT","U":429012394816,"u":429012394816,"pu":429012384776,"b":[],"a":[["77021.10","0.0000"],["77021.20","524.4731"]],"st":1}}
{"stream":"btcusdt@depth@100ms","data":{"e":"depthUpdate","E":1789469134770,"T":1789469134665,"s":"BTCUSDT","ps":"BTCUSDT","U":429012400304,"u":429012400304,"pu":429012394816,"b":[["76939.40","0.0007"]],"a":[],"st":1}}
{"stream":"btcusdt@depth@100ms","data":{"e":"depthUpdate","E":1789469134886,"T":1789469134859,"s":"BTCUSDT","ps":"BTCUSDT","U":429012401365,"u":429012402129,"pu":429012400304,"b":[],"a":[["77021.20","524.4724"],["77698.50","0.0025"],["77698.80","0.0000"]],"st":1}}
{"stream":"btcusdt@depth@100ms","data":{"e":"depthUpdate","E":1789469135006,"T":1789469134995,"s":"BTCUSDT","ps":"BTCUSDT","U":429012402483,"u":429012403447,"pu":429012402129,"b":[],"a":[["77021.20","524.4713"],["77021.70","680.5572"]],"st":1}}
{"stream":"btcusdt@depth@100ms","data":{"e":"depthUpdate","E":1789469135354,"T":1789469135351,"s":"BTCUSDT","ps":"BTCUSDT","U":429012405828,"u":429012406766,"pu":429012403447,"b":[],"a":[["77021.20","524.4690"],["77021.70","680.5581"],["77040.40","0.0000"]],"st":1}}
{"stream":"btcusdt@depth@100ms","data":{"e":"depthUpdate","E":1789469135482,"T":1789469135474,"s":"BTCUSDT","ps":"BTCUSDT","U":429012407036,"u":429012407872,"pu":429012406766,"b":[["77020.90","73.5481"]],"a":[["77021.20","354.1914"],["77021.70","680.5595"],["77047.00","0.0000"],["77698.70","0.0000"]],"st":1}}
{"stream":"btcusdt@depth@100ms","data":{"e":"depthUpdate","E":1789469135586,"T":1789469135496,"s":"BTCUSDT","ps":"BTCUSDT","U":429012407947,"u":429012408039,"pu":429012407872,"b":[["77020.90","97.8704"]],"a":[["77021.20","329.9922"]],"st":1}}
{"stream":"btcusdt@depth@100ms","data":{"e":"depthUpdate","E":1789469135778,"T":1789469135684,"s":"BTCUSDT","ps":"BTCUSDT","U":429012409419,"u":429012409626,"pu":429012408039,"b":[["76970.60","0.0051"]],"a":[["77698.50","0.0050"]],"st":1}}
{"stream":"btcusdt@depth@100ms","data":{"e":"depthUpdate","E":1789469136425,"T":1789469136315,"s":"BTCUSDT","ps":"BTCUSDT","U":429012415129,"u":429012415129,"pu":429012409626,"b":[["73100.00","0.0107"]],"a":[],"st":1}}
{"stream":"btcusdt@depth@100ms","data":{"e":"depthUpdate","E":1789469136627,"T":1789469136526,"s":"BTCUSDT","ps":"BTCUSDT","U":429012416874,"u":429012416874,"pu":429012415129,"b":[],"a":[["77060.60","0.0007"]],"st":1}}
{"stream":"btcusdt@depth@100ms","data":{"e":"depthUpdate","E":1789469137171,"T":1789469137163,"s":"BTCUSDT","ps":"BTCUSDT","U":429012421407,"u":429012422107,"pu":429012416874,"b":[],"a":[["77021.20","329.9901"],["77021.60","650.0234"]],"st":1}}
{"stream":"btcusdt@depth@100ms","data":{"e":"depthUpdate","E":1789469137279,"T":1789469137178,"s":"BTCUSDT","ps":"BTCUSDT","U":429012422196,"u":429012422196,"pu":429012422107,"b":[],"a":[["77021.70","680.5602"]],"st":1}}
{"stream":"btcusdt@depth@100ms","data":{"e":"depthUpdate","E":1789469137413,"T":1789469137398,"s":"BTCUSDT","ps":"BTCUSDT","U":429012423220,"u":429012423854,"pu":429012422196,"b":[["76939.40","0.0000"]],"a":[["77021.20","329.9663"]],"st":1}}
{"stream":"btcusdt@depth@100ms","data":{"e":"depthUpdate","E":1789469137553,"T":1789469137541,"s":"BTCUSDT","ps":"BTCUSDT","U":429012424339,"u":429012425114,"pu":429012423854,"b":[["73168.60","0.0000"],["73168.70","0.0020"]],"a":[["77021.20","329.9656"],["77021.70","680.5617"]],"st":1}}
{"stream":"btcusdt@depth@100ms","data":{"e":"depthUpdate","E":1789469137687,"T":1789469137586,"s":"BTCUSDT","ps":"BTCUSDT","U":429012425478,"u":429012425478,"pu":429012425114,"b":[["77020.90","97.8691"],["77021.00","0.0000"]],"a":[],"st":1}}
{"stream":"btcusdt@depth@100ms","data":{"e":"depthUpdate","E":1789469138284,"T":1789469138182,"s":"BTCUSDT","ps":"BTCUSDT","U":429012430093,"u":429012430093,"pu":429012425478,"b":[["76998.10","0.2490"]],"a":[],"st":1}}
{"stream":"btcusdt@depth@100ms","data":{"e":"depthUpdate","E":1789469138524,"T":1789469138423,"s":"BTCUSDT","ps":"BTCUSDT","U":429012432155,"u":429012432155,"pu":429012430093,"b":[["76998.10","0.3320"]],"a":[],"st":1}}
{"stream":"btcusdt@depth@100ms","data":{"e":"depthUpdate","E":1789469139308,"T":1789469139220,"s":"BTCUSDT","ps":"BTCUSDT","U":429012439145,"u":429012439246,"pu":429012432155,"b":[],"a":[["77021.20","329.9649"],["77021.60","650.0241"]],"st":1}}
{"stream":"btcusdt@depth@100ms","data":{"e":"depthUpdate","E":1789469139414,"T":1789469139358,"s":"BTCUSDT","ps":"BTCUSDT","U":429012439650,"u":429012440245,"pu":429012439246,"b":[["73169.80","0.0000"],["75095.30","0.0010"]],"a":[["77021.20","329.9639"],["77060.60","0.0000"]],"st":1}}
{"stream":"btcusdt@depth@100ms","data":{"e":"depthUpdate","E":1789469139534,"T":1789469139474,"s":"BTCUSDT","ps":"BTCUSDT","U":429012440731,"u":429012441184,"pu":429012440245,"b":[["75095.30","0.0000"]],"a":[["77021.20","329.9628"],["77021.60","650.0262"]],"st":1}}
{"stream":"btcusdt@depth@100ms","data":{"e":"depthUpdate","E":1789469139890,"T":1789469139853,"s":"BTCUSDT","ps":"BTCUSDT","U":429012443813,"u":429012444551,"pu":429012441184,"b":[],"a":[["77021.20","329.9618"],["77021.60","650.0272"],["77698.20","0.0105"],["77698.50","0.0025"]],"st":1}}
{"stream":"btcusdt@depth@100ms","data":{"e":"depthUpdate","E":1789469140400,"T":1789469140298,"s":"BTCUSDT","ps":"BTCUSDT","U":429012450107,"u":429012450107,"pu":429012444551,"b":[],"a":[["77698.50","0.0000"]],"st":1}}
{"stream":"btcusdt@depth@100ms","data":{"e":"depthUpdate","E":1789469140656,"T":1789469140597,"s":"BTCUSDT","ps":"BTCUSDT","U":429012454133,"u":429012454912,"pu":429012450107,"b":[["77020.90","97.8645"]],"a":[["77698.20","0.0130"]],"st":1}}
{"stream":"btcusdt@depth@100ms","data":{"e":"depthUpdate","E":1789469141036,"T":1789469141004,"s":"BTCUSDT","ps":"BTCUSDT","U":429012459451,"u":429012460504,"pu":429012454912,"b":[],"a":[["77021.20","183.9767"]],"st":1}}
{"stream":"btcusdt@depth@100ms","data":{"e":"depthUpdate","E":1789469141382,"T":1789469141365,"s":"BTCUSDT","ps":"BTCUSDT","U":429012463394,"u":429012464183,"pu":429012460504,"b":[],"a":[["77021.20","183.9749"],["77021.60","650.0282"]],"st":1}}
{"stream":"btcusdt@depth@100ms","data":{"e":"depthUpdate","E":1789469141507,"T":1789469141454,"s":"BTCUSDT","ps":"BTCUSDT","U":429012464573,"u":429012465039,"pu":429012464183,"b":[["77020.90","97.8605"]],"a":[["77021.20","183.9705"],["77021.60","650.0304"]],"st":1}}
{"stream":"btcusdt@depth@100ms","data":{"e":"depthUpdate","E":1789469141722,"T":1789469141661,"s":"BTCUSDT","ps":"BTCUSDT","U":429012466693,"u":429012467080,"pu":429012465039,"b":[["38510.60","0.0016"]],"a":[["77021.20","183.9695"]],"st":1}}
{"stream":"btcusdt@depth@100ms","data":{"e":"depthUpdate","E":1789469141882,"T":1789469141780,"s":"BTCUSDT","ps":"BTCUSDT","U":429012468102,"u":429012468102,"pu":429012467080,"b":[],"a":[["77021.60","650.0314"]],"st":1}}
{"stream":"btcusdt@depth@100ms","data":{"e":"depthUpdate","E":1789469142386,"T":1789469142285,"s":"BTCUSDT","ps":"BTCUSDT","U":429012472804,"u":429012472804,"pu":429012468102,"b":[["38483.00","0.0000"]],"a":[],"st":1}}
{"stream":"btcusdt@depth@100ms","data":{"e":"depthUpdate","E":1789469142926,"T":1789469142825,"s":"BTCUSDT","ps":"BTCUSDT","U":429012476562,"u":429012476562,"pu":429012472804,"b":[["73169.90","0.0020"]],"a":[],"st":1}}
{"stream":"btcusdt@depth@100ms","data":{"e":"depthUpdate","E":1789469143534,"T":1789469143425,"s":"BTCUSDT","ps":"BTCUSDT","U":429012481055,"u":429012481055,"pu":429012476562,"b":[],"a":[["77021.20","183.9635"]],"st":1}}
{"stream":"btcusdt@depth@100ms","data":{"e":"depthUpdate","E":1789469143666,"T":1789469143644,"s":"BTCUSDT","ps":"BTCUSDT","U":429012482210,"u":429012482948,"pu":429012481055,"b":[["73168.70","0.0000"]],"a":[["77021.20","183.9628"]],"st":1}}
{"stream":"btcusdt@depth@100ms","data":{"e":"depthUpdate","E":1789469143842,"T":1789469143825,"s":"BTCUSDT","ps":"BTCUSDT","U":429012483798,"u":429012484694,"pu":429012482948,"b":[],"a":[["77021.20","183.9606"],["77021.60","650.0329"],["77047.70","0.0051"]],"st":1}}
{"stream":"btcusdt@depth@100ms","data":{"e":"depthUpdate","E":1789469143996,"T":1789469143921,"s":"BTCUSDT","ps":"BTCUSDT","U":429012485381,"u":429012485643,"pu":429012484694,"b":[],"a":[["77021.20","183.9596"],["77021.60","650.0353"]],"st":1}}
{"stream":"btcusdt@depth@100ms","data":{"e":"depthUpdate","E":1789469144656,"T":1789469144553,"s":"BTCUSDT","ps":"BTCUSDT","U":429012491510,"u":429012491510,"pu":429012485643,"b":[],"a":[["77021.20","183.9588"]],"st":1}}
{"stream":"btcusdt@depth@100ms","data":{"e":"depthUpdate","E":1789469144862,"T":1789469144771,"s":"BTCUSDT","ps":"BTCUSDT","U":429012493756,"u":429012493829,"pu":429012491510,"b":[],"a":[["77021.60","650.0361"],["77697.90","0.0025"],["77698.20","0.0105"]],"st":1}}
{"stream":"btcusdt@depth@100ms","data":{"e":"depthUpdate","E":1789469145622,"T":1789469145546,"s":"BTCUSDT","ps":"BTCUSDT","U":429012501667,"u":429012501971,"pu":429012493829,"b":[["77020.90","97.6947"]],"a":[["77698.20","0.0080"]],"st":1}}
{"stream":"btcusdt@depth@100ms","data":{"e":"depthUpdate","E":1789469145746,"T":1789469145735,"s":"BTCUSDT","ps":"BTCUSDT","U":429012502835,"u":429012504010,"pu":429012501971,"b":[["77020.80","92.2907"]],"a":[["77021.20","83.2847"],["78308.80","0.0000"]],"st":1}}
{"stream":"btcusdt@depth@100ms","data":{"e":"depthUpdate","E":1789469145868,"T":1789469145827,"s":"BTCUSDT","ps":"BTCUSDT","U":429012504318,"u":429012504860,"pu":429012504010,"b":[],"a":[["77021.20","83.2840"],["77697.90","0.0050"]],"st":1}}
{"stream":"btcusdt@depth@100ms","data":{"e":"depthUpdate","E":1789469146134,"T":1789469146108,"s":"BTCUSDT","ps":"BTCUSDT","U":429012506389,"u":429012507593,"pu":429012504860,"b":[],"a":[["77021.20","83.2764"],["77021.60","650.0384"]],"st":1}}
{"stream":"btcusdt@depth@100ms","data":{"e":"depthUpdate","E":1789469146406,"T":1789469146296,"s":"BTCUSDT","ps":"BTCUSDT","U":429012509297,"u":429012509297,"pu":429012507593,"b":[],"a":[["77021.20","83.2752"]],"st":1}}
{"stream":"btcusdt@depth@100ms","data":{"e":"depthUpdate","E":1789469146530,"T":1789469146409,"s":"BTCUSDT","ps":"BTCUSDT","U":429012510424,"u":429012510424,"pu":429012509297,"b":[],"a":[["77021.70","680.5629"]],"st":1}}
{"stream":"btcusdt@depth@100ms","data":{"e":"depthUpdate","E":1789469148662,"T":1789469148592,"s":"BTCUSDT","ps":"BTCUSDT","U":429012528740,"u":429012528993,"pu":429012510424,"b":[],"a":[["77021.20","83.2728"],["77021.70","680.5653"]],"st":1}}
{"stream":"btcusdt@depth@100ms","data":{"e":"depthUpdate","E":1789469148870,"T":1789469148762,"s":"BTCUSDT","ps":"BTCUSDT","U":429012530148,"u":429012530148,"pu":429012528993,"b":[],"a":[["78308.80","0.0020"]],"st":1}}
{"stream":"btcusdt@depth@100ms","data":{"e":"depthUpdate","E":1789469149876,"T":1789469149809,"s":"BTCUSDT","ps":"BTCUSDT","U":429012539697,"u":429012540005,"pu":429012530148,"b":[["73169.90","0.0000"],["73170.00","0.0020"]],"a":[["77697.70","0.0025"],["77697.90","0.0025"]],"st":1}}
{"stream":"btcusdt@depth@100ms","data":{"e":"depthUpdate","E":1789469150198,"T":1789469150068,"s":"BTCUSDT","ps":"BTCUSDT","U":429012543233,"u":429012543233,"pu":429012540005,"b":[["73169.90","0.0020"]],"a":[],"st":1}}
{"stream":"btcusdt@depth@100ms","data":{"e":"depthUpdate","E":1789469150440,"T":1789469150438,"s":"BTCUSDT","ps":"BTCUSDT","U":429012546506,"u":429012547681,"pu":429012543233,"b":[],"a":[["77021.20","0.0000"],["77021.30","0.0000"],["77021.60","633.1922"],["77026.40","520.0000"]],"st":1}}
{"stream":"btcusdt@depth@100ms","data":{"e":"depthUpdate","E":1789469150544,"T":1789469150536,"s":"BTCUSDT","ps":"BTCUSDT","U":429012547763,"u":429012548857,"pu":429012547681,"b":[["76789.40","0.0010"],["76789.60","0.0010"],["76789.70","0.0000"],["76789.80","0.0000"],["76789.90","0.0010"]],"a":[["77026.40","650.0000"],["77026.60","60.9197"],["77026.70","45.6491"],["77028.60","30.3771"],["77029.70","30.3771"],["77030.10","60.7846"],["77030.20","30.3771"],["77031.30","91.1313"],["77031.90","30.3771"],["77032.80","30.3771"],["77037.60","30.3771"],["77252.20","0.0000"],["77252.30","0.0000"],["77252.40","0.0000"],["77252.50","42.0673"],["77252.80","0.0010"],["77253.00","19.9139"],["77253.30","0.0020"],["77697.90","0.0000"]],"st":1}}
{"stream":"btcusdt@depth@100ms","data":{"e":"depthUpdate","E":1789469150646,"T":1789469150573,"s":"BTCUSDT","ps":"BTCUSDT","U":429012548889,"u":429012549247,"pu":429012548857,"b":[],"a":[["77026.50","45.6484"],["77029.90","30.3771"],["77033.00","30.3771"],["77034.90","30.3771"],["77035.00","30.3771"],["77039.30","30.3771"],["77041.50","30.3771"]],"st":1}}
{"stream":"btcusdt@depth@100ms","data":{"e":"depthUpdate","E":1789469150838,"T":1789469150802,"s":"BTCUSDT","ps":"BTCUSDT","U":429012550800,"u":429012551580,"pu":429012549247,"b":[],"a":[["77021.60","633.1914"],["77697.60","0.0025"]],"st":1}}
{"stream":"btcusdt@depth@100ms","data":{"e":"depthUpdate","E":1789469150984,"T":1789469150876,"s":"BTCUSDT","ps":"BTCUSDT","U":429012552081,"u":429012552081,"pu":429012551580,"b":[],"a":[["77026.40","650.0008"]],"st":1}}
{"stream":"btcusdt@depth@100ms","data":{"e":"depthUpdate","E":1789469151190,"T":1789469151148,"s":"BTCUSDT","ps":"BTCUSDT","U":429012554136,"u":429012555532,"pu":429012552081,"b":[],"a":[["77021.60","633.1884"]],"st":1}}
{"stream":"btcusdt@depth@100ms","data":{"e":"depthUpdate","E":1789469151306,"T":1789469151166,"s":"BTCUSDT","ps":"BTCUSDT","U":429012555652,"u":429012555742,"pu":429012555532,"b":[],"a":[["77026.40","650.0031"]],"st":1}}
{"stream":"btcusdt@depth@100ms","data":{"e":"depthUpdate","E":1789469151442,"T":1789469151333,"s":"BTCUSDT","ps":"BTCUSDT","U":429012557313,"u":429012557313,"pu":429012555742,"b":[],"a":[["77026.40","650.0038"]],"st":1}}
{"stream":"btcusdt@depth@100ms","data":{"e":"depthUpdate","E":1789469151842,"T":1789469151735,"s":"BTCUSDT","ps":"BTCUSDT","U":429012561477,"u":429012561477,"pu":429012557313,"b":[],"a":[["77021.60","633.1820"]],"st":1}}
{"stream":"btcusdt@depth@100ms","data":{"e":"depthUpdate","E":1789469152248,"T":1789469152220,"s":"BTCUSDT","ps":"BTCUSDT","U":429012565557,"u":429012566218,"pu":429012561477,"b":[["76946.90","0.0012"]],"a":[["77021.60","633.1812"],["77092.50","0.0000"],["77166.50","0.0043"]],"st":1}}
{"stream":"btcusdt@depth@100ms","data":{"e":"depthUpdate","E":1789469152656,"T":1789469152573,"s":"BTCUSDT","ps":"BTCUSDT","U":429012569247,"u":429012569403,"pu":429012566218,"b":[["76865.50","0.0012"]],"a":[["77047.70","0.0000"]],"st":1}}
{"stream":"btcusdt@depth@100ms","data":{"e":"depthUpdate","E":1789469153114,"T":1789469153012,"s":"BTCUSDT","ps":"BTCUSDT","U":429012572879,"u":429012572879,"pu":429012569403,"b":[["76784.10","0.0012"]],"a":[],"st":1}}
{"stream":"btcusdt@depth@100ms","data":{"e":"depthUpdate","E":1789469153620,"T":1789469153507,"s":"BTCUSDT","ps":"BTCUSDT","U":429012576751,"u":429012576751,"pu":429012572879,"b":[["77020.90","97.6939"]],"a":[],"st":1}}
{"stream":"btcusdt@depth@100ms","data":{"e":"depthUpdate","E":1789469153910,"T":1789469153893,"s":"BTCUSDT","ps":"BTCUSDT","U":429012578650,"u":429012579240,"pu":429012576751,"b":[],"a":[["77021.60","633.1774"],["77026.50","45.6506"]],"st":1}}
{"stream":"btcusdt@depth@100ms","data":{"e":"depthUpdate","E":1789469154172,"T":1789469154168,"s":"BTCUSDT","ps":"BTCUSDT","U":429012580299,"u":429012580905,"pu":429012579240,"b":[],"a":[["77026.50","45.6522"]],"st":1}}
{"stream":"btcusdt@depth@100ms","data":{"e":"depthUpdate","E":1789469154914,"T":1789469154812,"s":"BTCUSDT","ps":"BTCUSDT","U":429012585992,"u":429012585992,"pu":429012580905,"b":[["77019.50","64.9764"]],"a":[],"st":1}}
{"stream":"btcusdt@depth@100ms","data":{"e":"depthUpdate","E":1789469155260,"T":1789469155151,"s":"BTCUSDT","ps":"BTCUSDT","U":429012590193,"u":429012590193,"pu":429012585992,"b":[],"a":[["77021.60","633.1276"]],"st":1}}
{"stream":"btcusdt@depth@100ms","data":{"e":"depthUpdate","E":1789469155386,"T":1789469155284,"s":"BTCUSDT","ps":"BTCUSDT","U":429012591830,"u":429012591830,"pu":429012590193,"b":[],"a":[["77697.40","0.0025"],["77697.70","0.0000"]],"st":1}}
{"stream":"btcusdt@depth@100ms","data":{"e":"depthUpdate","E":1789469155506,"T":1789469155392,"s":"BTCUSDT","ps":"BTCUSDT","U":429012593062,"u":429012593062,"pu":429012591830,"b":[["77020.90","97.6376"]],"a":[],"st":1}}
{"stream":"btcusdt@depth@100ms","data":{"e":"depthUpdate","E":1789469155718,"T":1789469155616,"s":"BTCUSDT","ps":"BTCUSDT","U":429012596041,"u":429012596041,"pu":429012593062,"b":[],"a":[["77697.60","0.0000"]],"st":1}}
{"stream":"btcusdt@depth@100ms","data":{"e":"depthUpdate","E":1789469155964,"T":1789469155948,"s":"BTCUSDT","ps":"BTCUSDT","U":429012599205,"u":429012601242,"pu":429012596041,"b":[],"a":[["77021.60","533.2650"],["77026.40","1235.0038"],["77697.40","0.0050"]],"st":1}}
{"stream":"btcusdt@depth@100ms","data":{"e":"depthUpdate","E":1789469156072,"T":1789469155953,"s":"BTCUSDT","ps":"BTCUSDT","U":429012601303,"u":429012601303,"pu":429012601242,"b":[],"a":[["77026.40","1300.0038"]],"st":1}}
{"stream":"btcusdt@depth@100ms","data":{"e":"depthUpdate","E":1789469156206,"T":1789469156088,"s":"BTCUSDT","ps":"BTCUSDT","U":429012603030,"u":429012603030,"pu":429012601303,"b":[],"a":[["77021.60","533.2643"]],"st":1}}
{"stream":"btcusdt@depth@100ms","data":{"e":"depthUpdate","E":1789469156334,"T":1789469156324,"s":"BTCUSDT","ps":"BTCUSDT","U":429012604950,"u":429012605921,"pu":429012603030,"b":[["76784.10","0.0000"],["76865.50","0.0000"]],"a":[["77021.60","533.2636"],["77026.40","1300.0045"],["77037.90","0.0007"]],"st":1}}
{"stream":"btcusdt@depth@100ms","data":{"e":"depthUpdate","E":1789469156442,"T":1789469156340,"s":"BTCUSDT","ps":"BTCUSDT","U":429012606093,"u":429012606093,"pu":429012605921,"b":[["76946.90","0.0000"]],"a":[],"st":1}}
{"stream":"btcusdt@depth@100ms","data":{"e":"depthUpdate","E":1789469156596,"T":1789469156560,"s":"BTCUSDT","ps":"BTCUSDT","U":429012607688,"u":429012608390,"pu":429012606093,"b":[],"a":[["77021.60","533.2615"],["77037.90","0.0017"]],"st":1}}
{"stream":"btcusdt@depth@100ms","data":{"e":"depthUpdate","E":1789469156764,"T":1789469156652,"s":"BTCUSDT","ps":"BTCUSDT","U":429012609467,"u":429012609467,"pu":429012608390,"b":[],"a":[["77037.90","0.0028"]],"st":1}}
{"stream":"btcusdt@depth@100ms","data":{"e":"depthUpdate","E":1789469156942,"T":1789469156921,"s":"BTCUSDT","ps":"BTCUSDT","U":429012611452,"u":429012612147,"pu":429012609467,"b":[["73169.90","0.0000"],["73170.00","0.0020"]],"a":[],"st":1}}
{"stream":"btcusdt@depth@100ms","data":{"e":"depthUpdate","E":1789469157178,"T":1789469157056,"s":"BTCUSDT","ps":"BTCUSDT","U":429012613446,"u":429012613446,"pu":429012612147,"b":[],"a":[["77021.60","533.2605"]],"st":1}}
{"stream":"btcusdt@depth@100ms","data":{"e":"depthUpdate","E":1789469157600,"T":1789469157487,"s":"BTCUSDT","ps":"BTCUSDT","U":429012616795,"u":429012616795,"pu":429012613446,"b":[["76962.70","0.0012"]],"a":[],"st":1}}
{"stream":"btcusdt@depth@100ms","data":{"e":"depthUpdate","E":1789469158048,"T":1789469157946,"s":"BTCUSDT","ps":"BTCUSDT","U":429012620221,"u":429012620221,"pu":429012616795,"b":[["76904.90","0.0012"]],"a":[],"st":1}}
{"stream":"btcusdt@depth@100ms","data":{"e":"depthUpdate","E":1789469158448,"T":1789469158358,"s":"BTCUSDT","ps":"BTCUSDT","U":429012623368,"u":429012623488,"pu":429012620221,"b":[["38510.80","0.0016"],["76847.10","0.0012"]],"a":[],"st":1}}
{"stream":"btcusdt@depth@100ms","data":{"e":"depthUpdate","E":1789469158818,"T":1789469158761,"s":"BTCUSDT","ps":"BTCUSDT","U":429012626246,"u":429012626609,"pu":429012623488,"b":[],"a":[["77021.60","533.2585"],["77037.00","0.0010"],["77039.90","0.0012"]],"st":1}}
{"stream":"btcusdt@depth@100ms","data":{"e":"depthUpdate","E":1789469158960,"T":1789469158859,"s":"BTCUSDT","ps":"BTCUSDT","U":429012627405,"u":429012627405,"pu":429012626609,"b":[],"a":[["77021.60","533.2577"]],"st":1}}
{"stream":"btcusdt@depth@100ms","data":{"e":"depthUpdate","E":1789469159078,"T":1789469159010,"s":"BTCUSDT","ps":"BTCUSDT","U":429012628699,"u":429012629244,"pu":429012627405,"b":[],"a":[["77021.60","533.2564"],["77037.00","0.0033"]],"st":1}}
{"stream":"btcusdt@depth@100ms","data":{"e":"depthUpdate","E":1789469159232,"T":1789469159213,"s":"BTCUSDT","ps":"BTCUSDT","U":429012630566,"u":429012631490,"pu":429012629244,"b":[["38510.60","0.0000"]],"a":[["77037.00","0.0041"],["80500.00","10.4478"]],"st":1}}
{"stream":"btcusdt@depth@100ms","data":{"e":"depthUpdate","E":1789469159350,"T":1789469159248,"s":"BTCUSDT","ps":"BTCUSDT","U":429012631859,"u":429012631859,"pu":429012631490,"b":[],"a":[["77097.80","0.0012"]],"st":1}}
{"stream":"btcusdt@depth@100ms","data":{"e":"depthUpdate","E":1789469159856,"T":1789469159804,"s":"BTCUSDT","ps":"BTCUSDT","U":429012637642,"u":429012638326,"pu":429012631859,"b":[],"a":[["77021.60","432.9504"],["77155.60","0.0012"],["77697.10","0.0025"],["77697.40","0.0025"]],"st":1}}
{"stream":"btcusdt@depth@100ms","data":{"e":"depthUpdate","E":1789469159966,"T":1789469159952,"s":"BTCUSDT","ps":"BTCUSDT","U":429012638991,"u":429012640157,"pu":429012638326,"b":[],"a":[["77021.60","432.9435"],["77037.00","585.0041"],["79580.00","0.0000"]],"st":1}}
{"stream":"btcusdt@depth@100ms","data":{"e":"depthUpdate","E":1789469160076,"T":1789469160009,"s":"BTCUSDT","ps":"BTCUSDT","U":429012640377,"u":429012640728,"pu":429012640157,"b":[["77021.00","0.0231"]],"a":[["77021.50","0.0007"],["77021.60","432.9387"],["77037.40","33.4529"],["77038.70","33.4529"],["77040.30","33.4529"],["77042.80","33.4529"],["77043.00","33.4529"]],"st":1}}
{"stream":"btcusdt@depth@100ms","data":{"e":"depthUpdate","E":1789469160192,"T":1789469160084,"s":"BTCUSDT","ps":"BTCUSDT","U":429012641698,"u":429012641703,"pu":429012640728,"b":[["76789.40","0.0000"],["76789.60","0.0010"],["76789.80","0.0010"],["76789.90","0.0000"],["76790.00","0.0010"]],"a":[["77252.50","42.0663"],["77252.60","12.3954"],["77253.20","12.3964"],["77253.30","0.0000"]],"st":1}}
{"stream":"btcusdt@depth@100ms","data":{"e":"depthUpdate","E":1789469160326,"T":1789469160220,"s":"BTCUSDT","ps":"BTCUSDT","U":429012643155,"u":429012643155,"pu":429012641703,"b":[["75859.40","0.0000"]],"a":[],"st":1}}
{"stream":"btcusdt@depth@100ms","data":{"e":"depthUpdate","E":1789469160476,"T":1789469160401,"s":"BTCUSDT","ps":"BTCUSDT","U":429012644614,"u":429012645012,"pu":429012643155,"b":[["77020.90","97.2877"],["77021.00","0.0000"]],"a":[["77021.50","0.0238"],["77697.40","0.0000"]],"st":1}}
{"stream":"btcusdt@depth@100ms","data":{"e":"depthUpdate","E":1789469160610,"T":1789469160526,"s":"BTCUSDT","ps":"BTCUSDT","U":429012645841,"u":429012646357,"pu":429012645012,"b":[["76789.50","0.0010"],["76789.60","0.0000"],["76789.70","0.0010"],["76789.80","0.0000"],["76789.90","0.0010"],["76790.00","0.0000"],["77021.00","0.0025"]],"a":[["77021.50","0.0213"],["77252.50","42.0673"],["77252.60","12.3944"],["77252.70","0.0010"],["77252.80","0.0000"],["77252.90","0.0010"],["77253.00","19.9129"],["77253.10","0.0020"],["77253.20","12.3944"]],"st":1}}
{"stream":"btcusdt@depth@100ms","data":{"e":"depthUpdate","E":1789469160736,"T":1789469160659,"s":"BTCUSDT","ps":"BTCUSDT","U":429012647538,"u":429012648228,"pu":429012646357,"b":[["77021.00","0.0032"]],"a":[["77021.50","0.0206"],["77697.10","0.0050"]],"st":1}}
{"stream":"btcusdt@depth@100ms","data":{"e":"depthUpdate","E":1789469160838,"T":1789469160774,"s":"BTCUSDT","ps":"BTCUSDT","U":429012649189,"u":429012649720,"pu":429012648228,"b":[["77021.00","0.0053"]],"a":[["77021.50","0.0185"],["77021.60","432.9327"],["77036.90","0.0012"]],"st":1}}
{"stream":"btcusdt@depth@100ms","data":{"e":"depthUpdate","E":1789469160950,"T":1789469160853,"s":"BTCUSDT","ps":"BTCUSDT","U":429012650448,"u":429012650548,"pu":429012649720,"b":[],"a":[["77036.90","0.0021"],["77253.00","19.9149"],["77253.10","0.0000"]],"st":1}}
{"stream":"btcusdt@depth@100ms","data":{"e":"depthUpdate","E":1789469161052,"T":1789469160992,"s":"BTCUSDT","ps":"BTCUSDT","U":429012652070,"u":429012652829,"pu":429012650548,"b":[["75272.90","0.0000"],["77021.00","0.0069"]],"a":[["77021.50","0.0169"],["77036.90","0.0037"]],"st":1}}
{"stream":"btcusdt@depth@100ms","data":{"e":"depthUpdate","E":1789469161160,"T":1789469161059,"s":"BTCUSDT","ps":"BTCUSDT","U":429012653887,"u":429012653888,"pu":429012652829,"b":[["76789.50","0.0000"],["76789.60","0.0010"]],"a":[["77252.80","0.0010"],["77252.90","0.0000"]],"st":1}}
{"stream":"btcusdt@depth@100ms","data":{"e":"depthUpdate","E":1789469161478,"T":1789469161381,"s":"BTCUSDT","ps":"BTCUSDT","U":429012657571,"u":429012657599,"pu":429012653888,"b":[["77021.00","0.0079"]],"a":[["77021.50","0.0159"]],"st":1}}
{"stream":"btcusdt@depth@100ms","data":{"e":"depthUpdate","E":1789469161590,"T":1789469161548,"s":"BTCUSDT","ps":"BTCUSDT","U":429012658690,"u":429012659553,"pu":429012657599,"b":[["76789.70","0.0000"],["76789.80","0.0010"]],"a":[["77021.50","0.0151"]],"st":1}}
{"stream":"btcusdt@depth@100ms","data":{"e":"depthUpdate","E":1789469161808,"T":1789469161706,"s":"BTCUSDT","ps":"BTCUSDT","U":429012660787,"u":429012660899,"pu":429012659553,"b":[["75436.00","0.0000"]],"a":[["77036.90","0.0045"]],"st":1}}
{"stream":"btcusdt@depth@100ms","data":{"e":"depthUpdate","E":1789469161984,"T":1789469161876,"s":"BTCUSDT","ps":"BTCUSDT","U":429012662361,"u":429012662361,"pu":429012660899,"b":[],"a":[["77155.60","0.0000"]],"st":1}}
{"stream":"btcusdt@depth@100ms","data":{"e":"depthUpdate","E":1789469162340,"T":1789469162220,"s":"BTCUSDT","ps":"BTCUSDT","U":429012665125,"u":429012665125,"pu":429012662361,"b":[],"a":[["77039.90","0.0000"]],"st":1}}
{"stream":"btcusdt@depth@100ms","data":{"e":"depthUpdate","E":1789469162502,"T":1789469162393,"s":"BTCUSDT","ps":"BTCUSDT","U":429012666542,"u":429012666542,"pu":429012665125,"b":[["75602.00","0.0000"]],"a":[],"st":1}}
{"stream":"btcusdt@depth@100ms","data":{"e":"depthUpdate","E":1789469162694,"T":1789469162666,"s":"BTCUSDT","ps":"BTCUSDT","U":429012668008,"u":429012668561,"pu":429012666542,"b":[["76847.10","0.0000"],["77021.00","0.0000"]],"a":[["77021.00","0.1868"]],"st":1}}
{"stream":"btcusdt@depth@100ms","data":{"e":"depthUpdate","E":1789469162804,"T":1789469162782,"s":"BTCUSDT","ps":"BTCUSDT","U":429012668766,"u":429012669281,"pu":429012668561,"b":[["75771.30","0.0000"],["76789.50","0.0010"],["76789.60","0.0010"],["76789.70","0.0010"],["76789.80","0.0000"],["76789.90","0.0000"]],"a":[["77252.10","0.0010"],["77252.20","0.0010"],["77252.30","0.0010"],["77252.40","0.0020"],["77252.50","42.0663"],["77252.70","0.0000"],["77252.80","0.0000"],["77253.00","19.9129"]],"st":1}}
