{"success":true,"ret_msg":"subscribe","conn_id":"d967ikkn0ine3iqmjc30-koqj","req_id":"sub1","op":"subscribe"}
{"topic":"orderbook.50.BTCUSDT","ts":1789299657452,"type":"snapshot","data":{"s":"BTCUSDT","b":[["77140.5","0.216593"],["77140.4","0.324084"],["77140.3","0.131763"],["77140.2","0.177862"],["77140.1","0.131763"],["77140","0.072313"],["77139.9","0.072313"],["77139.8","0.053571"],["77131.1","0.000248"],["77090.8","0.003831"],["77025.6","0.000943"],["77000","0.002114"],["76948.6","0.000787"],["76909","0.003835"],["76893.6","0.002495"],["76886","0.000259"],["76871.8","0.001931"],["76869","0.000387"],["76800","0.061159"],["76771.5","0.000538"],["76766.2","0.001208"],["76765.5","0.000644"],["76758","0.000249"],["76727.2","0.003835"],["76723","0.000543"],["76692","0.000249"],["76684.2","0.000228"],["76666.1","0.000249"],["76666","0.003712"],["76661.2","0.000249"],["76600","0.00292"],["76548.8","0.002495"],["76547","0.001"],["76545.9","0.000184"],["76545.4","0.003835"],["76523.3","0.001"],["76484.6","0.000279"],["76471.3","0.001"],["76445.4","0.000644"],["76440","0.000398"],["76434.2","0.000387"],["76430.3","0.000187"],["76400","0.06091"],["76371.7","0.000259"],["76363.6","0.003835"],["76339.2","0.000646"],["76332.9","0.001208"],["76278.6","0.001108"],["76271.2","0.00021"],["76204","0.002495"]],"a":[["77140.6","0.324006"],["77140.7","0.240088"],["77140.8","0.177784"],["77140.9","0.131763"],["77141","0.131763"],["77141.1","0.177861"],["77141.2","0.053571"],["77267.6","0.000182"],["77273.4","0.000247"],["77321.6","0.002"],["77334.2","0.000902"],["77397.1","0.000248"],["77400","0.002111"],["77400.2","0.000259"],["77405.7","0.000643"],["77409.9","0.001113"],["77411.5","0.002044"],["77454.4","0.003831"],["77461.2","0.000247"],["77488.9","0.001886"],["77496.6","0.000101"],["77500","0.015116"],["77582.2","0.00034"],["77583.2","0.002492"],["77586.3","0.000342"],["77600","0.060847"],["77630.2","0.001014"],["77632.9","0.001206"],["77636.1","0.000537"],["77636.2","0.003831"],["77641.7","0.000218"],["77642.2","0.000333"],["77667.8","0.000192"],["77672.8","0.000278"],["77704.9","0.001"],["77711.4","0.000397"],["77725.8","0.000643"],["77738.6","0.000386"],["77757.8","0.001"],["77760.6","0.000227"],["77781.9","0.001"],["77800","0.002111"],["77818","0.003831"],["77862","0.000246"],["77875.7","0.001385"],["77893.2","0.000101"],["77894.7","0.000124"],["77914","0.000211"],["77914.4","0.000259"],["77923.8","0.000541"]],"u":3734358,"seq":2189232157},"cts":1789299655598}
{"topic":"orderbook.1.BTCUSDT","ts":1789299655643,"type":"snapshot","data":{"s":"BTCUSDT","b":[["77140.5","0.216593"]],"a":[["77140.6","0.324006"]],"u":1980705,"seq":2189232157},"cts":1789299655598}
{"success":true,"ret_msg":"pong","conn_id":"d967ikkn0ine3iqmjc30-koqj","req_id":"p1","op":"ping"}
{"topic":"orderbook.50.BTCUSDT","ts":1789299658933,"type":"delta","data":{"s":"BTCUSDT","b":[["77140.3","0"],["77139.8","0"],["76200","0.002114"],["76181.8","0.003835"]],"a":[["77141.2","0"],["77928","0.002492"]],"u":3734359,"seq":2189232166},"cts":1789299658878}
{"topic":"orderbook.1.BTCUSDT","ts":1789299659913,"type":"snapshot","data":{"s":"BTCUSDT","b":[["77140.5","0.216593"]],"a":[["77140.6","0.324006"]],"u":1980705,"seq":2189232166},"cts":1789299658878}
{"topic":"publicTrade.BTCUSDT","ts":1789299660724,"type":"snapshot","data":[{"i":"2100000000188691524","T":1789299660688,"p":"77140.5","v":"0.00389","S":"Sell","seq":2189232173,"s":"BTCUSDT","BT":false,"RPI":false}]}
{"topic":"orderbook.50.BTCUSDT","ts":1789299660733,"type":"delta","data":{"s":"BTCUSDT","b":[["77140.5","0.212703"]],"a":[],"u":3734360,"seq":2189232173},"cts":1789299660688}
{"topic":"orderbook.1.BTCUSDT","ts":1789299660734,"type":"snapshot","data":{"s":"BTCUSDT","b":[["77140.5","0.212703"]],"a":[["77140.6","0.324006"]],"u":1980706,"seq":2189232173},"cts":1789299660688}
{"topic":"orderbook.50.BTCUSDT","ts":1789299663932,"type":"delta","data":{"s":"BTCUSDT","b":[["77140.3","0.240088"],["77139.8","0.053571"],["76200","0"],["76181.8","0"]],"a":[["77141.2","0.053571"],["77928","0"]],"u":3734361,"seq":2189232180},"cts":1789299663878}
{"topic":"publicTrade.BTCUSDT","ts":1789299665818,"type":"snapshot","data":[{"i":"2100000000188691528","T":1789299665782,"p":"77140.5","v":"0.00389","S":"Sell","seq":2189232186,"s":"BTCUSDT","BT":false,"RPI":false}]}
{"topic":"orderbook.1.BTCUSDT","ts":1789299665824,"type":"snapshot","data":{"s":"BTCUSDT","b":[["77140.5","0.208813"]],"a":[["77140.6","0.324006"]],"u":1980707,"seq":2189232186},"cts":1789299665782}
{"topic":"orderbook.50.BTCUSDT","ts":1789299665832,"type":"delta","data":{"s":"BTCUSDT","b":[["77140.5","0.208813"]],"a":[],"u":3734362,"seq":2189232186},"cts":1789299665782}
{"topic":"orderbook.1.BTCUSDT","ts":1789299668914,"type":"snapshot","data":{"s":"BTCUSDT","b":[["77140.5","0.208813"]],"a":[["77140.6","0.324006"]],"u":1980707,"seq":2189232186},"cts":1789299665782}
{"topic":"orderbook.1.BTCUSDT","ts":1789299668924,"type":"snapshot","data":{"s":"BTCUSDT","b":[["77140.5","0.000078"]],"a":[["77140.7","0.240088"]],"u":1980708,"seq":2189232202},"cts":1789299668878}
{"topic":"orderbook.50.BTCUSDT","ts":1789299668932,"type":"delta","data":{"s":"BTCUSDT","b":[["77140.5","0.000078"],["77140.4","0"],["77140.3","0"],["77140.2","0"],["77139.8","0"],["76200","0.002114"],["76181.8","0.003835"],["76146.7","0.000079"],["76146","0.000228"]],"a":[["77140.6","0"],["77141.1","0"],["77141.2","0"],["77928","0.002492"],["77963.7","0.000183"],["77993.4","0.000057"]],"u":3734363,"seq":2189232202},"cts":1789299668878}
{"topic":"orderbook.50.BTCUSDT","ts":1789299669152,"type":"delta","data":{"s":"BTCUSDT","b":[],"a":[["77757.7","0.001"],["77757.8","0"]],"u":3734364,"seq":2189232203},"cts":1789299669105}
{"topic":"publicTrade.BTCUSDT","ts":1789299670925,"type":"snapshot","data":[{"i":"2100000000188691533","T":1789299670888,"p":"77140.5","v":"0.000078","S":"Sell","seq":2189232212,"s":"BTCUSDT","BT":false,"RPI":false},{"i":"2100000000188691534","T":1789299670888,"p":"77140.1","v":"0.003812","S":"Sell","seq":2189232212,"s":"BTCUSDT","BT":false,"RPI":false}]}
{"topic":"orderbook.50.BTCUSDT","ts":1789299670932,"type":"delta","data":{"s":"BTCUSDT","b":[["77140.5","0"],["77140.1","0.127951"],["76132.9","0.000079"]],"a":[],"u":3734365,"seq":2189232212},"cts":1789299670888}
{"topic":"orderbook.1.BTCUSDT","ts":1789299670934,"type":"snapshot","data":{"s":"BTCUSDT","b":[["77140.1","0.127951"]],"a":[["77140.7","0.240088"]],"u":1980709,"seq":2189232212},"cts":1789299670888}
{"topic":"publicTrade.BTCUSDT","ts":1789299671085,"type":"snapshot","data":[{"i":"2100000000188691535","T":1789299671049,"p":"77140.1","v":"0.00008","S":"Sell","seq":2189232213,"s":"BTCUSDT","BT":false,"RPI":false}]}
{"topic":"orderbook.50.BTCUSDT","ts":1789299671093,"type":"delta","data":{"s":"BTCUSDT","b":[["77140.1","0.127871"]],"a":[],"u":3734366,"seq":2189232213},"cts":1789299671049}
{"topic":"orderbook.1.BTCUSDT","ts":1789299671094,"type":"snapshot","data":{"s":"BTCUSDT","b":[["77140.1","0.127871"]],"a":[["77140.7","0.240088"]],"u":1980710,"seq":2189232213},"cts":1789299671049}
{"topic":"orderbook.50.BTCUSDT","ts":1789299671213,"type":"delta","data":{"s":"BTCUSDT","b":[["76523.3","0"],["76523","0.001"]],"a":[],"u":3734367,"seq":2189232214},"cts":1789299671168}
{"topic":"orderbook.50.BTCUSDT","ts":1789299671312,"type":"delta","data":{"s":"BTCUSDT","b":[],"a":[["77757.6","0.001"],["77757.7","0"]],"u":3734368,"seq":2189232215},"cts":1789299671259}
{"topic":"publicTrade.BTCUSDT","ts":1789299672352,"type":"snapshot","data":[{"i":"2100000000188691536","T":1789299672316,"p":"77140.7","v":"0.000012","S":"Buy","seq":2189232216,"s":"BTCUSDT","BT":false,"RPI":false}]}
{"topic":"orderbook.1.BTCUSDT","ts":1789299672353,"type":"snapshot","data":{"s":"BTCUSDT","b":[["77140.1","0.127871"]],"a":[["77140.7","0.240076"]],"u":1980711,"seq":2189232216},"cts":1789299672316}
{"topic":"orderbook.50.BTCUSDT","ts":1789299672372,"type":"delta","data":{"s":"BTCUSDT","b":[],"a":[["77140.7","0.240076"]],"u":3734369,"seq":2189232216},"cts":1789299672316}
{"topic":"orderbook.50.BTCUSDT","ts":1789299673932,"type":"delta","data":{"s":"BTCUSDT","b":[["77140.6","0.324084"],["77140.5","0.240087"],["77140.4","0.177861"],["77140.3","0.131763"],["77140.2","0.097612"],["76200","0"],["76181.8","0"],["76146.7","0"],["76146","0"],["76132.9","0"]],"a":[["77141.1","0.131763"],["77141.2","0.097612"],["77141.3","0.072313"],["77141.4","0.053571"],["77923.8","0"],["77928","0"],["77963.7","0"],["77993.4","0"]],"u":3734370,"seq":2189232231},"cts":1789299673888}
{"topic":"orderbook.1.BTCUSDT","ts":1789299673934,"type":"snapshot","data":{"s":"BTCUSDT","b":[["77140.6","0.324084"]],"a":[["77140.7","0.240076"]],"u":1980712,"seq":2189232231},"cts":1789299673888}
{"topic":"orderbook.50.BTCUSDT","ts":1789299674373,"type":"delta","data":{"s":"BTCUSDT","b":[["76523.3","0.001"],["76523","0"]],"a":[],"u":3734371,"seq":2189232232},"cts":1789299674322}
{"topic":"orderbook.50.BTCUSDT","ts":1789299674433,"type":"delta","data":{"s":"BTCUSDT","b":[],"a":[["77757.6","0"],["77758","0.001"]],"u":3734372,"seq":2189232233},"cts":1789299674388}
{"topic":"publicTrade.BTCUSDT","ts":1789299676025,"type":"snapshot","data":[{"i":"2100000000188691540","T":1789299675989,"p":"77140.6","v":"0.003889","S":"Sell","seq":2189232242,"s":"BTCUSDT","BT":false,"RPI":false}]}
{"topic":"orderbook.50.BTCUSDT","ts":1789299676032,"type":"delta","data":{"s":"BTCUSDT","b":[["77140.6","0.320195"]],"a":[],"u":3734373,"seq":2189232242},"cts":1789299675989}
{"topic":"orderbook.1.BTCUSDT","ts":1789299676034,"type":"snapshot","data":{"s":"BTCUSDT","b":[["77140.6","0.320195"]],"a":[["77140.7","0.240076"]],"u":1980713,"seq":2189232242},"cts":1789299675989}
{"topic":"orderbook.1.BTCUSDT","ts":1789299678923,"type":"snapshot","data":{"s":"BTCUSDT","b":[["77140.5","0.240087"]],"a":[["77140.7","0.240076"]],"u":1980714,"seq":2189232253},"cts":1789299678878}
{"topic":"orderbook.50.BTCUSDT","ts":1789299678933,"type":"delta","data":{"s":"BTCUSDT","b":[["77140.6","0"],["77140","0"],["77139.9","0"],["76200","0.002114"],["76181.8","0.003835"],["76146.7","0.000079"]],"a":[["77141.4","0"],["77923.8","0.000541"]],"u":3734374,"seq":2189232253},"cts":1789299678878}
{"topic":"orderbook.50.BTCUSDT","ts":1789299679453,"type":"delta","data":{"s":"BTCUSDT","b":[],"a":[["77757.9","0.001"],["77758","0"]],"u":3734375,"seq":2189232254},"cts":1789299679415}
{"topic":"publicTrade.BTCUSDT","ts":1789299681134,"type":"snapshot","data":[{"i":"2100000000188691544","T":1789299681098,"p":"77140.5","v":"0.00389","S":"Sell","seq":2189232272,"s":"BTCUSDT","BT":false,"RPI":false}]}
{"topic":"orderbook.1.BTCUSDT","ts":1789299681144,"type":"snapshot","data":{"s":"BTCUSDT","b":[["77140.5","0.236197"]],"a":[["77140.7","0.240076"]],"u":1980715,"seq":2189232272},"cts":1789299681098}
{"topic":"orderbook.50.BTCUSDT","ts":1789299681153,"type":"delta","data":{"s":"BTCUSDT","b":[["77140.5","0.236197"]],"a":[],"u":3734376,"seq":2189232272},"cts":1789299681098}
{"topic":"orderbook.1.BTCUSDT","ts":1789299683944,"type":"snapshot","data":{"s":"BTCUSDT","b":[["77140.5","0.236197"]],"a":[["77140.6","0.324084"]],"u":1980716,"seq":2189232283},"cts":1789299683898}
{"success":false,"ret_msg":"Invalid symbol :[orderbook.50.NOSUCHSYM]","conn_id":"d967ikkn0ine3iqmjc30-koqj","op":"subscribe"}
